[2024-03-29T16:15:30.757+0000] {processor.py:161} INFO - Started process (PID=39) to work on /opt/airflow/dags/emr_add_step_dag.py
[2024-03-29T16:15:30.758+0000] {processor.py:830} INFO - Processing file /opt/airflow/dags/emr_add_step_dag.py for tasks to queue
[2024-03-29T16:15:30.760+0000] {logging_mixin.py:188} INFO - [2024-03-29T16:15:30.760+0000] {dagbag.py:540} INFO - Filling up the DagBag from /opt/airflow/dags/emr_add_step_dag.py
[2024-03-29T16:15:30.773+0000] {logging_mixin.py:188} INFO - [2024-03-29T16:15:30.771+0000] {dagbag.py:350} ERROR - Failed to import: /opt/airflow/dags/emr_add_step_dag.py
Traceback (most recent call last):
  File "/home/airflow/.local/lib/python3.8/site-packages/airflow/models/dagbag.py", line 346, in parse
    loader.exec_module(new_module)
  File "<frozen importlib._bootstrap_external>", line 843, in exec_module
  File "<frozen importlib._bootstrap>", line 219, in _call_with_frames_removed
  File "/opt/airflow/dags/emr_add_step_dag.py", line 2, in <module>
    import dagfactory
ModuleNotFoundError: No module named 'dagfactory'
[2024-03-29T16:15:30.774+0000] {processor.py:842} WARNING - No viable dags retrieved from /opt/airflow/dags/emr_add_step_dag.py
[2024-03-29T16:15:30.790+0000] {processor.py:183} INFO - Processing /opt/airflow/dags/emr_add_step_dag.py took 0.035 seconds
[2024-03-29T16:16:01.294+0000] {processor.py:161} INFO - Started process (PID=47) to work on /opt/airflow/dags/emr_add_step_dag.py
[2024-03-29T16:16:01.295+0000] {processor.py:830} INFO - Processing file /opt/airflow/dags/emr_add_step_dag.py for tasks to queue
[2024-03-29T16:16:01.297+0000] {logging_mixin.py:188} INFO - [2024-03-29T16:16:01.296+0000] {dagbag.py:540} INFO - Filling up the DagBag from /opt/airflow/dags/emr_add_step_dag.py
[2024-03-29T16:16:01.307+0000] {logging_mixin.py:188} INFO - [2024-03-29T16:16:01.305+0000] {dagbag.py:350} ERROR - Failed to import: /opt/airflow/dags/emr_add_step_dag.py
Traceback (most recent call last):
  File "/home/airflow/.local/lib/python3.8/site-packages/airflow/models/dagbag.py", line 346, in parse
    loader.exec_module(new_module)
  File "<frozen importlib._bootstrap_external>", line 843, in exec_module
  File "<frozen importlib._bootstrap>", line 219, in _call_with_frames_removed
  File "/opt/airflow/dags/emr_add_step_dag.py", line 2, in <module>
    import dagfactory
ModuleNotFoundError: No module named 'dagfactory'
[2024-03-29T16:16:01.308+0000] {processor.py:842} WARNING - No viable dags retrieved from /opt/airflow/dags/emr_add_step_dag.py
[2024-03-29T16:16:01.333+0000] {processor.py:183} INFO - Processing /opt/airflow/dags/emr_add_step_dag.py took 0.040 seconds
[2024-03-29T16:16:31.620+0000] {processor.py:161} INFO - Started process (PID=55) to work on /opt/airflow/dags/emr_add_step_dag.py
[2024-03-29T16:16:31.622+0000] {processor.py:830} INFO - Processing file /opt/airflow/dags/emr_add_step_dag.py for tasks to queue
[2024-03-29T16:16:31.624+0000] {logging_mixin.py:188} INFO - [2024-03-29T16:16:31.624+0000] {dagbag.py:540} INFO - Filling up the DagBag from /opt/airflow/dags/emr_add_step_dag.py
[2024-03-29T16:16:31.649+0000] {logging_mixin.py:188} INFO - [2024-03-29T16:16:31.642+0000] {dagbag.py:350} ERROR - Failed to import: /opt/airflow/dags/emr_add_step_dag.py
Traceback (most recent call last):
  File "/home/airflow/.local/lib/python3.8/site-packages/airflow/models/dagbag.py", line 346, in parse
    loader.exec_module(new_module)
  File "<frozen importlib._bootstrap_external>", line 843, in exec_module
  File "<frozen importlib._bootstrap>", line 219, in _call_with_frames_removed
  File "/opt/airflow/dags/emr_add_step_dag.py", line 2, in <module>
    import dagfactory
ModuleNotFoundError: No module named 'dagfactory'
[2024-03-29T16:16:31.658+0000] {processor.py:842} WARNING - No viable dags retrieved from /opt/airflow/dags/emr_add_step_dag.py
[2024-03-29T16:16:31.682+0000] {processor.py:183} INFO - Processing /opt/airflow/dags/emr_add_step_dag.py took 0.067 seconds
[2024-03-29T16:17:01.898+0000] {processor.py:161} INFO - Started process (PID=63) to work on /opt/airflow/dags/emr_add_step_dag.py
[2024-03-29T16:17:01.898+0000] {processor.py:830} INFO - Processing file /opt/airflow/dags/emr_add_step_dag.py for tasks to queue
[2024-03-29T16:17:01.899+0000] {logging_mixin.py:188} INFO - [2024-03-29T16:17:01.899+0000] {dagbag.py:540} INFO - Filling up the DagBag from /opt/airflow/dags/emr_add_step_dag.py
[2024-03-29T16:17:01.909+0000] {logging_mixin.py:188} INFO - [2024-03-29T16:17:01.907+0000] {dagbag.py:350} ERROR - Failed to import: /opt/airflow/dags/emr_add_step_dag.py
Traceback (most recent call last):
  File "/home/airflow/.local/lib/python3.8/site-packages/airflow/models/dagbag.py", line 346, in parse
    loader.exec_module(new_module)
  File "<frozen importlib._bootstrap_external>", line 843, in exec_module
  File "<frozen importlib._bootstrap>", line 219, in _call_with_frames_removed
  File "/opt/airflow/dags/emr_add_step_dag.py", line 2, in <module>
    import dagfactory
ModuleNotFoundError: No module named 'dagfactory'
[2024-03-29T16:17:01.909+0000] {processor.py:842} WARNING - No viable dags retrieved from /opt/airflow/dags/emr_add_step_dag.py
[2024-03-29T16:17:01.933+0000] {processor.py:183} INFO - Processing /opt/airflow/dags/emr_add_step_dag.py took 0.037 seconds
[2024-03-29T16:24:36.538+0000] {processor.py:161} INFO - Started process (PID=39) to work on /opt/airflow/dags/emr_add_step_dag.py
[2024-03-29T16:24:36.539+0000] {processor.py:830} INFO - Processing file /opt/airflow/dags/emr_add_step_dag.py for tasks to queue
[2024-03-29T16:24:36.551+0000] {logging_mixin.py:188} INFO - [2024-03-29T16:24:36.542+0000] {dagbag.py:540} INFO - Filling up the DagBag from /opt/airflow/dags/emr_add_step_dag.py
[2024-03-29T16:24:46.034+0000] {logging_mixin.py:188} INFO - [2024-03-29T16:24:46.030+0000] {dagbag.py:350} ERROR - Failed to import: /opt/airflow/dags/emr_add_step_dag.py
Traceback (most recent call last):
  File "/home/airflow/.local/lib/python3.8/site-packages/airflow/models/dagbag.py", line 346, in parse
    loader.exec_module(new_module)
  File "<frozen importlib._bootstrap_external>", line 843, in exec_module
  File "<frozen importlib._bootstrap>", line 219, in _call_with_frames_removed
  File "/opt/airflow/dags/emr_add_step_dag.py", line 44, in <module>
    dag_factory = dagfactory.DagFactory(
  File "/home/airflow/.local/lib/python3.8/site-packages/dagfactory/dagfactory.py", line 38, in __init__
    DagFactory._validate_config_filepath(config_filepath=config_filepath)
  File "/home/airflow/.local/lib/python3.8/site-packages/dagfactory/dagfactory.py", line 51, in _validate_config_filepath
    raise DagFactoryConfigException(
dagfactory.exceptions.DagFactoryConfigException: DAG Factory `config_filepath` must be absolute path
[2024-03-29T16:24:46.035+0000] {processor.py:842} WARNING - No viable dags retrieved from /opt/airflow/dags/emr_add_step_dag.py
[2024-03-29T16:24:46.064+0000] {processor.py:183} INFO - Processing /opt/airflow/dags/emr_add_step_dag.py took 9.531 seconds
[2024-03-29T16:25:16.619+0000] {processor.py:161} INFO - Started process (PID=54) to work on /opt/airflow/dags/emr_add_step_dag.py
[2024-03-29T16:25:16.620+0000] {processor.py:830} INFO - Processing file /opt/airflow/dags/emr_add_step_dag.py for tasks to queue
[2024-03-29T16:25:16.623+0000] {logging_mixin.py:188} INFO - [2024-03-29T16:25:16.623+0000] {dagbag.py:540} INFO - Filling up the DagBag from /opt/airflow/dags/emr_add_step_dag.py
[2024-03-29T16:25:18.139+0000] {logging_mixin.py:188} INFO - [2024-03-29T16:25:18.137+0000] {dagbag.py:350} ERROR - Failed to import: /opt/airflow/dags/emr_add_step_dag.py
Traceback (most recent call last):
  File "/home/airflow/.local/lib/python3.8/site-packages/airflow/models/dagbag.py", line 346, in parse
    loader.exec_module(new_module)
  File "<frozen importlib._bootstrap_external>", line 843, in exec_module
  File "<frozen importlib._bootstrap>", line 219, in _call_with_frames_removed
  File "/opt/airflow/dags/emr_add_step_dag.py", line 44, in <module>
    dag_factory = dagfactory.DagFactory(
  File "/home/airflow/.local/lib/python3.8/site-packages/dagfactory/dagfactory.py", line 38, in __init__
    DagFactory._validate_config_filepath(config_filepath=config_filepath)
  File "/home/airflow/.local/lib/python3.8/site-packages/dagfactory/dagfactory.py", line 51, in _validate_config_filepath
    raise DagFactoryConfigException(
dagfactory.exceptions.DagFactoryConfigException: DAG Factory `config_filepath` must be absolute path
[2024-03-29T16:25:18.139+0000] {processor.py:842} WARNING - No viable dags retrieved from /opt/airflow/dags/emr_add_step_dag.py
[2024-03-29T16:25:18.167+0000] {processor.py:183} INFO - Processing /opt/airflow/dags/emr_add_step_dag.py took 1.553 seconds
[2024-03-29T16:25:48.983+0000] {processor.py:161} INFO - Started process (PID=62) to work on /opt/airflow/dags/emr_add_step_dag.py
[2024-03-29T16:25:48.984+0000] {processor.py:830} INFO - Processing file /opt/airflow/dags/emr_add_step_dag.py for tasks to queue
[2024-03-29T16:25:48.986+0000] {logging_mixin.py:188} INFO - [2024-03-29T16:25:48.985+0000] {dagbag.py:540} INFO - Filling up the DagBag from /opt/airflow/dags/emr_add_step_dag.py
[2024-03-29T16:25:49.217+0000] {logging_mixin.py:188} INFO - [2024-03-29T16:25:49.215+0000] {dagbag.py:350} ERROR - Failed to import: /opt/airflow/dags/emr_add_step_dag.py
Traceback (most recent call last):
  File "/home/airflow/.local/lib/python3.8/site-packages/airflow/models/dagbag.py", line 346, in parse
    loader.exec_module(new_module)
  File "<frozen importlib._bootstrap_external>", line 843, in exec_module
  File "<frozen importlib._bootstrap>", line 219, in _call_with_frames_removed
  File "/opt/airflow/dags/emr_add_step_dag.py", line 44, in <module>
    dag_factory = dagfactory.DagFactory(
  File "/home/airflow/.local/lib/python3.8/site-packages/dagfactory/dagfactory.py", line 38, in __init__
    DagFactory._validate_config_filepath(config_filepath=config_filepath)
  File "/home/airflow/.local/lib/python3.8/site-packages/dagfactory/dagfactory.py", line 51, in _validate_config_filepath
    raise DagFactoryConfigException(
dagfactory.exceptions.DagFactoryConfigException: DAG Factory `config_filepath` must be absolute path
[2024-03-29T16:25:49.218+0000] {processor.py:842} WARNING - No viable dags retrieved from /opt/airflow/dags/emr_add_step_dag.py
[2024-03-29T16:25:49.232+0000] {processor.py:183} INFO - Processing /opt/airflow/dags/emr_add_step_dag.py took 0.252 seconds
[2024-03-29T16:26:02.141+0000] {processor.py:161} INFO - Started process (PID=63) to work on /opt/airflow/dags/emr_add_step_dag.py
[2024-03-29T16:26:02.142+0000] {processor.py:830} INFO - Processing file /opt/airflow/dags/emr_add_step_dag.py for tasks to queue
[2024-03-29T16:26:02.143+0000] {logging_mixin.py:188} INFO - [2024-03-29T16:26:02.143+0000] {dagbag.py:540} INFO - Filling up the DagBag from /opt/airflow/dags/emr_add_step_dag.py
[2024-03-29T16:26:02.520+0000] {logging_mixin.py:188} INFO - [2024-03-29T16:26:02.517+0000] {dagbag.py:350} ERROR - Failed to import: /opt/airflow/dags/emr_add_step_dag.py
Traceback (most recent call last):
  File "/home/airflow/.local/lib/python3.8/site-packages/dagfactory/dagfactory.py", line 72, in _load_config
    stream=open(config_filepath, "r", encoding="utf-8"),
FileNotFoundError: [Errno 2] No such file or directory: '/mnt/e/reps/highliner/artifacts/dags/dag_definition_ex1.yaml'

The above exception was the direct cause of the following exception:

Traceback (most recent call last):
  File "/home/airflow/.local/lib/python3.8/site-packages/airflow/models/dagbag.py", line 346, in parse
    loader.exec_module(new_module)
  File "<frozen importlib._bootstrap_external>", line 843, in exec_module
  File "<frozen importlib._bootstrap>", line 219, in _call_with_frames_removed
  File "/opt/airflow/dags/emr_add_step_dag.py", line 44, in <module>
    dag_factory = dagfactory.DagFactory(
  File "/home/airflow/.local/lib/python3.8/site-packages/dagfactory/dagfactory.py", line 39, in __init__
    self.config: Dict[str, Any] = DagFactory._load_config(
  File "/home/airflow/.local/lib/python3.8/site-packages/dagfactory/dagfactory.py", line 76, in _load_config
    raise DagFactoryConfigException("Invalid DAG Factory config file") from err
dagfactory.exceptions.DagFactoryConfigException: Invalid DAG Factory config file
[2024-03-29T16:26:02.520+0000] {processor.py:842} WARNING - No viable dags retrieved from /opt/airflow/dags/emr_add_step_dag.py
[2024-03-29T16:26:02.534+0000] {processor.py:183} INFO - Processing /opt/airflow/dags/emr_add_step_dag.py took 0.398 seconds
[2024-03-29T16:26:04.333+0000] {processor.py:161} INFO - Started process (PID=64) to work on /opt/airflow/dags/emr_add_step_dag.py
[2024-03-29T16:26:04.334+0000] {processor.py:830} INFO - Processing file /opt/airflow/dags/emr_add_step_dag.py for tasks to queue
[2024-03-29T16:26:04.336+0000] {logging_mixin.py:188} INFO - [2024-03-29T16:26:04.336+0000] {dagbag.py:540} INFO - Filling up the DagBag from /opt/airflow/dags/emr_add_step_dag.py
[2024-03-29T16:26:04.739+0000] {logging_mixin.py:188} INFO - [2024-03-29T16:26:04.736+0000] {dagbag.py:350} ERROR - Failed to import: /opt/airflow/dags/emr_add_step_dag.py
Traceback (most recent call last):
  File "/home/airflow/.local/lib/python3.8/site-packages/dagfactory/dagfactory.py", line 72, in _load_config
    stream=open(config_filepath, "r", encoding="utf-8"),
FileNotFoundError: [Errno 2] No such file or directory: '/mnt/e/reps/highliner/artifacts/dags/dag_definition_ex1.yaml'

The above exception was the direct cause of the following exception:

Traceback (most recent call last):
  File "/home/airflow/.local/lib/python3.8/site-packages/airflow/models/dagbag.py", line 346, in parse
    loader.exec_module(new_module)
  File "<frozen importlib._bootstrap_external>", line 843, in exec_module
  File "<frozen importlib._bootstrap>", line 219, in _call_with_frames_removed
  File "/opt/airflow/dags/emr_add_step_dag.py", line 44, in <module>
    dag_factory = dagfactory.DagFactory(
  File "/home/airflow/.local/lib/python3.8/site-packages/dagfactory/dagfactory.py", line 39, in __init__
    self.config: Dict[str, Any] = DagFactory._load_config(
  File "/home/airflow/.local/lib/python3.8/site-packages/dagfactory/dagfactory.py", line 76, in _load_config
    raise DagFactoryConfigException("Invalid DAG Factory config file") from err
dagfactory.exceptions.DagFactoryConfigException: Invalid DAG Factory config file
[2024-03-29T16:26:04.739+0000] {processor.py:842} WARNING - No viable dags retrieved from /opt/airflow/dags/emr_add_step_dag.py
[2024-03-29T16:26:04.755+0000] {processor.py:183} INFO - Processing /opt/airflow/dags/emr_add_step_dag.py took 0.425 seconds
[2024-03-29T16:28:01.006+0000] {processor.py:161} INFO - Started process (PID=39) to work on /opt/airflow/dags/emr_add_step_dag.py
[2024-03-29T16:28:01.079+0000] {processor.py:830} INFO - Processing file /opt/airflow/dags/emr_add_step_dag.py for tasks to queue
[2024-03-29T16:28:01.190+0000] {logging_mixin.py:188} INFO - [2024-03-29T16:28:01.190+0000] {dagbag.py:540} INFO - Filling up the DagBag from /opt/airflow/dags/emr_add_step_dag.py
[2024-03-29T16:28:09.541+0000] {logging_mixin.py:188} INFO - [2024-03-29T16:28:09.532+0000] {dagbag.py:350} ERROR - Failed to import: /opt/airflow/dags/emr_add_step_dag.py
Traceback (most recent call last):
  File "/home/airflow/.local/lib/python3.8/site-packages/dagfactory/dagfactory.py", line 72, in _load_config
    stream=open(config_filepath, "r", encoding="utf-8"),
FileNotFoundError: [Errno 2] No such file or directory: '/mnt/e/reps/highliner/artifacts/dags/dag_definition_ex1.yaml'

The above exception was the direct cause of the following exception:

Traceback (most recent call last):
  File "/home/airflow/.local/lib/python3.8/site-packages/airflow/models/dagbag.py", line 346, in parse
    loader.exec_module(new_module)
  File "<frozen importlib._bootstrap_external>", line 843, in exec_module
  File "<frozen importlib._bootstrap>", line 219, in _call_with_frames_removed
  File "/opt/airflow/dags/emr_add_step_dag.py", line 44, in <module>
    dag_factory = dagfactory.DagFactory(
  File "/home/airflow/.local/lib/python3.8/site-packages/dagfactory/dagfactory.py", line 39, in __init__
    self.config: Dict[str, Any] = DagFactory._load_config(
  File "/home/airflow/.local/lib/python3.8/site-packages/dagfactory/dagfactory.py", line 76, in _load_config
    raise DagFactoryConfigException("Invalid DAG Factory config file") from err
dagfactory.exceptions.DagFactoryConfigException: Invalid DAG Factory config file
[2024-03-29T16:28:09.543+0000] {processor.py:842} WARNING - No viable dags retrieved from /opt/airflow/dags/emr_add_step_dag.py
[2024-03-29T16:28:09.610+0000] {processor.py:183} INFO - Processing /opt/airflow/dags/emr_add_step_dag.py took 9.614 seconds
[2024-03-29T16:28:39.930+0000] {processor.py:161} INFO - Started process (PID=53) to work on /opt/airflow/dags/emr_add_step_dag.py
[2024-03-29T16:28:39.955+0000] {processor.py:830} INFO - Processing file /opt/airflow/dags/emr_add_step_dag.py for tasks to queue
[2024-03-29T16:28:39.987+0000] {logging_mixin.py:188} INFO - [2024-03-29T16:28:39.982+0000] {dagbag.py:540} INFO - Filling up the DagBag from /opt/airflow/dags/emr_add_step_dag.py
[2024-03-29T16:28:41.916+0000] {logging_mixin.py:188} INFO - [2024-03-29T16:28:41.912+0000] {dagbag.py:350} ERROR - Failed to import: /opt/airflow/dags/emr_add_step_dag.py
Traceback (most recent call last):
  File "/home/airflow/.local/lib/python3.8/site-packages/dagfactory/dagfactory.py", line 72, in _load_config
    stream=open(config_filepath, "r", encoding="utf-8"),
FileNotFoundError: [Errno 2] No such file or directory: '/mnt/e/reps/highliner/artifacts/dags/dag_definition_ex1.yaml'

The above exception was the direct cause of the following exception:

Traceback (most recent call last):
  File "/home/airflow/.local/lib/python3.8/site-packages/airflow/models/dagbag.py", line 346, in parse
    loader.exec_module(new_module)
  File "<frozen importlib._bootstrap_external>", line 843, in exec_module
  File "<frozen importlib._bootstrap>", line 219, in _call_with_frames_removed
  File "/opt/airflow/dags/emr_add_step_dag.py", line 44, in <module>
    dag_factory = dagfactory.DagFactory(
  File "/home/airflow/.local/lib/python3.8/site-packages/dagfactory/dagfactory.py", line 39, in __init__
    self.config: Dict[str, Any] = DagFactory._load_config(
  File "/home/airflow/.local/lib/python3.8/site-packages/dagfactory/dagfactory.py", line 76, in _load_config
    raise DagFactoryConfigException("Invalid DAG Factory config file") from err
dagfactory.exceptions.DagFactoryConfigException: Invalid DAG Factory config file
[2024-03-29T16:28:41.916+0000] {processor.py:842} WARNING - No viable dags retrieved from /opt/airflow/dags/emr_add_step_dag.py
[2024-03-29T16:28:41.958+0000] {processor.py:183} INFO - Processing /opt/airflow/dags/emr_add_step_dag.py took 2.071 seconds
[2024-03-29T16:29:12.021+0000] {processor.py:161} INFO - Started process (PID=62) to work on /opt/airflow/dags/emr_add_step_dag.py
[2024-03-29T16:29:12.023+0000] {processor.py:830} INFO - Processing file /opt/airflow/dags/emr_add_step_dag.py for tasks to queue
[2024-03-29T16:29:12.026+0000] {logging_mixin.py:188} INFO - [2024-03-29T16:29:12.026+0000] {dagbag.py:540} INFO - Filling up the DagBag from /opt/airflow/dags/emr_add_step_dag.py
[2024-03-29T16:29:13.433+0000] {logging_mixin.py:188} INFO - [2024-03-29T16:29:13.420+0000] {dagbag.py:350} ERROR - Failed to import: /opt/airflow/dags/emr_add_step_dag.py
Traceback (most recent call last):
  File "/home/airflow/.local/lib/python3.8/site-packages/dagfactory/dagfactory.py", line 72, in _load_config
    stream=open(config_filepath, "r", encoding="utf-8"),
FileNotFoundError: [Errno 2] No such file or directory: '/mnt/e/reps/highliner/artifacts/dags/dag_definition_ex1.yaml'

The above exception was the direct cause of the following exception:

Traceback (most recent call last):
  File "/home/airflow/.local/lib/python3.8/site-packages/airflow/models/dagbag.py", line 346, in parse
    loader.exec_module(new_module)
  File "<frozen importlib._bootstrap_external>", line 843, in exec_module
  File "<frozen importlib._bootstrap>", line 219, in _call_with_frames_removed
  File "/opt/airflow/dags/emr_add_step_dag.py", line 44, in <module>
    dag_factory = dagfactory.DagFactory(
  File "/home/airflow/.local/lib/python3.8/site-packages/dagfactory/dagfactory.py", line 39, in __init__
    self.config: Dict[str, Any] = DagFactory._load_config(
  File "/home/airflow/.local/lib/python3.8/site-packages/dagfactory/dagfactory.py", line 76, in _load_config
    raise DagFactoryConfigException("Invalid DAG Factory config file") from err
dagfactory.exceptions.DagFactoryConfigException: Invalid DAG Factory config file
[2024-03-29T16:29:13.434+0000] {processor.py:842} WARNING - No viable dags retrieved from /opt/airflow/dags/emr_add_step_dag.py
[2024-03-29T16:29:13.546+0000] {processor.py:183} INFO - Processing /opt/airflow/dags/emr_add_step_dag.py took 1.540 seconds
[2024-03-29T16:29:43.792+0000] {processor.py:161} INFO - Started process (PID=70) to work on /opt/airflow/dags/emr_add_step_dag.py
[2024-03-29T16:29:43.795+0000] {processor.py:830} INFO - Processing file /opt/airflow/dags/emr_add_step_dag.py for tasks to queue
[2024-03-29T16:29:43.799+0000] {logging_mixin.py:188} INFO - [2024-03-29T16:29:43.799+0000] {dagbag.py:540} INFO - Filling up the DagBag from /opt/airflow/dags/emr_add_step_dag.py
[2024-03-29T16:29:44.784+0000] {logging_mixin.py:188} INFO - [2024-03-29T16:29:44.777+0000] {dagbag.py:350} ERROR - Failed to import: /opt/airflow/dags/emr_add_step_dag.py
Traceback (most recent call last):
  File "/home/airflow/.local/lib/python3.8/site-packages/dagfactory/dagfactory.py", line 72, in _load_config
    stream=open(config_filepath, "r", encoding="utf-8"),
FileNotFoundError: [Errno 2] No such file or directory: '/mnt/e/reps/highliner/artifacts/dags/dag_definition_ex1.yaml'

The above exception was the direct cause of the following exception:

Traceback (most recent call last):
  File "/home/airflow/.local/lib/python3.8/site-packages/airflow/models/dagbag.py", line 346, in parse
    loader.exec_module(new_module)
  File "<frozen importlib._bootstrap_external>", line 843, in exec_module
  File "<frozen importlib._bootstrap>", line 219, in _call_with_frames_removed
  File "/opt/airflow/dags/emr_add_step_dag.py", line 44, in <module>
    dag_factory = dagfactory.DagFactory(
  File "/home/airflow/.local/lib/python3.8/site-packages/dagfactory/dagfactory.py", line 39, in __init__
    self.config: Dict[str, Any] = DagFactory._load_config(
  File "/home/airflow/.local/lib/python3.8/site-packages/dagfactory/dagfactory.py", line 76, in _load_config
    raise DagFactoryConfigException("Invalid DAG Factory config file") from err
dagfactory.exceptions.DagFactoryConfigException: Invalid DAG Factory config file
[2024-03-29T16:29:44.785+0000] {processor.py:842} WARNING - No viable dags retrieved from /opt/airflow/dags/emr_add_step_dag.py
[2024-03-29T16:29:44.809+0000] {processor.py:183} INFO - Processing /opt/airflow/dags/emr_add_step_dag.py took 1.024 seconds
[2024-03-29T16:30:15.011+0000] {processor.py:161} INFO - Started process (PID=78) to work on /opt/airflow/dags/emr_add_step_dag.py
[2024-03-29T16:30:15.013+0000] {processor.py:830} INFO - Processing file /opt/airflow/dags/emr_add_step_dag.py for tasks to queue
[2024-03-29T16:30:15.015+0000] {logging_mixin.py:188} INFO - [2024-03-29T16:30:15.015+0000] {dagbag.py:540} INFO - Filling up the DagBag from /opt/airflow/dags/emr_add_step_dag.py
[2024-03-29T16:30:15.364+0000] {logging_mixin.py:188} INFO - [2024-03-29T16:30:15.359+0000] {dagbag.py:350} ERROR - Failed to import: /opt/airflow/dags/emr_add_step_dag.py
Traceback (most recent call last):
  File "/home/airflow/.local/lib/python3.8/site-packages/dagfactory/dagfactory.py", line 72, in _load_config
    stream=open(config_filepath, "r", encoding="utf-8"),
FileNotFoundError: [Errno 2] No such file or directory: '/mnt/e/reps/highliner/artifacts/dags/dag_definition_ex1.yaml'

The above exception was the direct cause of the following exception:

Traceback (most recent call last):
  File "/home/airflow/.local/lib/python3.8/site-packages/airflow/models/dagbag.py", line 346, in parse
    loader.exec_module(new_module)
  File "<frozen importlib._bootstrap_external>", line 843, in exec_module
  File "<frozen importlib._bootstrap>", line 219, in _call_with_frames_removed
  File "/opt/airflow/dags/emr_add_step_dag.py", line 44, in <module>
    dag_factory = dagfactory.DagFactory(
  File "/home/airflow/.local/lib/python3.8/site-packages/dagfactory/dagfactory.py", line 39, in __init__
    self.config: Dict[str, Any] = DagFactory._load_config(
  File "/home/airflow/.local/lib/python3.8/site-packages/dagfactory/dagfactory.py", line 76, in _load_config
    raise DagFactoryConfigException("Invalid DAG Factory config file") from err
dagfactory.exceptions.DagFactoryConfigException: Invalid DAG Factory config file
[2024-03-29T16:30:15.364+0000] {processor.py:842} WARNING - No viable dags retrieved from /opt/airflow/dags/emr_add_step_dag.py
[2024-03-29T16:30:15.393+0000] {processor.py:183} INFO - Processing /opt/airflow/dags/emr_add_step_dag.py took 0.385 seconds
[2024-03-29T16:38:39.949+0000] {processor.py:161} INFO - Started process (PID=39) to work on /opt/airflow/dags/emr_add_step_dag.py
[2024-03-29T16:38:39.950+0000] {processor.py:830} INFO - Processing file /opt/airflow/dags/emr_add_step_dag.py for tasks to queue
[2024-03-29T16:38:39.953+0000] {logging_mixin.py:188} INFO - [2024-03-29T16:38:39.952+0000] {dagbag.py:540} INFO - Filling up the DagBag from /opt/airflow/dags/emr_add_step_dag.py
[2024-03-29T16:38:41.190+0000] {logging_mixin.py:188} INFO - [2024-03-29T16:38:41.186+0000] {dagbag.py:350} ERROR - Failed to import: /opt/airflow/dags/emr_add_step_dag.py
Traceback (most recent call last):
  File "/home/airflow/.local/lib/python3.8/site-packages/airflow/models/dagbag.py", line 346, in parse
    loader.exec_module(new_module)
  File "<frozen importlib._bootstrap_external>", line 843, in exec_module
  File "<frozen importlib._bootstrap>", line 219, in _call_with_frames_removed
  File "/opt/airflow/dags/emr_add_step_dag.py", line 52, in <module>
    pipeline = parse_yaml_file(
  File "/opt/airflow/dags/emr_add_step_dag.py", line 48, in parse_yaml_file
    with open(abs_path, 'r') as file:
FileNotFoundError: [Errno 2] No such file or directory: '/mnt/e/reps/highliner/artifacts/dags/dag_definition_ex1.yaml'
[2024-03-29T16:38:41.191+0000] {processor.py:842} WARNING - No viable dags retrieved from /opt/airflow/dags/emr_add_step_dag.py
[2024-03-29T16:38:41.228+0000] {processor.py:183} INFO - Processing /opt/airflow/dags/emr_add_step_dag.py took 1.283 seconds
[2024-03-29T16:39:11.888+0000] {processor.py:161} INFO - Started process (PID=48) to work on /opt/airflow/dags/emr_add_step_dag.py
[2024-03-29T16:39:11.889+0000] {processor.py:830} INFO - Processing file /opt/airflow/dags/emr_add_step_dag.py for tasks to queue
[2024-03-29T16:39:11.890+0000] {logging_mixin.py:188} INFO - [2024-03-29T16:39:11.890+0000] {dagbag.py:540} INFO - Filling up the DagBag from /opt/airflow/dags/emr_add_step_dag.py
[2024-03-29T16:39:12.138+0000] {logging_mixin.py:188} INFO - [2024-03-29T16:39:12.136+0000] {dagbag.py:350} ERROR - Failed to import: /opt/airflow/dags/emr_add_step_dag.py
Traceback (most recent call last):
  File "/home/airflow/.local/lib/python3.8/site-packages/airflow/models/dagbag.py", line 346, in parse
    loader.exec_module(new_module)
  File "<frozen importlib._bootstrap_external>", line 843, in exec_module
  File "<frozen importlib._bootstrap>", line 219, in _call_with_frames_removed
  File "/opt/airflow/dags/emr_add_step_dag.py", line 52, in <module>
    pipeline = parse_yaml_file(
  File "/opt/airflow/dags/emr_add_step_dag.py", line 48, in parse_yaml_file
    with open(abs_path, 'r') as file:
FileNotFoundError: [Errno 2] No such file or directory: '/mnt/e/reps/highliner/artifacts/dags/dag_definition_ex1.yaml'
[2024-03-29T16:39:12.139+0000] {processor.py:842} WARNING - No viable dags retrieved from /opt/airflow/dags/emr_add_step_dag.py
[2024-03-29T16:39:12.149+0000] {processor.py:183} INFO - Processing /opt/airflow/dags/emr_add_step_dag.py took 0.264 seconds
[2024-03-29T16:39:42.204+0000] {processor.py:161} INFO - Started process (PID=56) to work on /opt/airflow/dags/emr_add_step_dag.py
[2024-03-29T16:39:42.205+0000] {processor.py:830} INFO - Processing file /opt/airflow/dags/emr_add_step_dag.py for tasks to queue
[2024-03-29T16:39:42.207+0000] {logging_mixin.py:188} INFO - [2024-03-29T16:39:42.207+0000] {dagbag.py:540} INFO - Filling up the DagBag from /opt/airflow/dags/emr_add_step_dag.py
[2024-03-29T16:39:42.473+0000] {logging_mixin.py:188} INFO - [2024-03-29T16:39:42.470+0000] {dagbag.py:350} ERROR - Failed to import: /opt/airflow/dags/emr_add_step_dag.py
Traceback (most recent call last):
  File "/home/airflow/.local/lib/python3.8/site-packages/airflow/models/dagbag.py", line 346, in parse
    loader.exec_module(new_module)
  File "<frozen importlib._bootstrap_external>", line 843, in exec_module
  File "<frozen importlib._bootstrap>", line 219, in _call_with_frames_removed
  File "/opt/airflow/dags/emr_add_step_dag.py", line 52, in <module>
    pipeline = parse_yaml_file(
  File "/opt/airflow/dags/emr_add_step_dag.py", line 48, in parse_yaml_file
    with open(abs_path, 'r') as file:
FileNotFoundError: [Errno 2] No such file or directory: '/mnt/e/reps/highliner/artifacts/dags/dag_definition_ex1.yaml'
[2024-03-29T16:39:42.474+0000] {processor.py:842} WARNING - No viable dags retrieved from /opt/airflow/dags/emr_add_step_dag.py
[2024-03-29T16:39:42.485+0000] {processor.py:183} INFO - Processing /opt/airflow/dags/emr_add_step_dag.py took 0.283 seconds
[2024-03-29T16:40:12.577+0000] {processor.py:161} INFO - Started process (PID=64) to work on /opt/airflow/dags/emr_add_step_dag.py
[2024-03-29T16:40:12.578+0000] {processor.py:830} INFO - Processing file /opt/airflow/dags/emr_add_step_dag.py for tasks to queue
[2024-03-29T16:40:12.580+0000] {logging_mixin.py:188} INFO - [2024-03-29T16:40:12.579+0000] {dagbag.py:540} INFO - Filling up the DagBag from /opt/airflow/dags/emr_add_step_dag.py
[2024-03-29T16:40:12.819+0000] {logging_mixin.py:188} INFO - [2024-03-29T16:40:12.816+0000] {dagbag.py:350} ERROR - Failed to import: /opt/airflow/dags/emr_add_step_dag.py
Traceback (most recent call last):
  File "/home/airflow/.local/lib/python3.8/site-packages/airflow/models/dagbag.py", line 346, in parse
    loader.exec_module(new_module)
  File "<frozen importlib._bootstrap_external>", line 843, in exec_module
  File "<frozen importlib._bootstrap>", line 219, in _call_with_frames_removed
  File "/opt/airflow/dags/emr_add_step_dag.py", line 52, in <module>
    pipeline = parse_yaml_file(
  File "/opt/airflow/dags/emr_add_step_dag.py", line 48, in parse_yaml_file
    with open(abs_path, 'r') as file:
FileNotFoundError: [Errno 2] No such file or directory: '/mnt/e/reps/highliner/artifacts/dags/dag_definition_ex1.yaml'
[2024-03-29T16:40:12.820+0000] {processor.py:842} WARNING - No viable dags retrieved from /opt/airflow/dags/emr_add_step_dag.py
[2024-03-29T16:40:12.842+0000] {processor.py:183} INFO - Processing /opt/airflow/dags/emr_add_step_dag.py took 0.268 seconds
[2024-03-29T16:40:43.777+0000] {processor.py:161} INFO - Started process (PID=72) to work on /opt/airflow/dags/emr_add_step_dag.py
[2024-03-29T16:40:43.777+0000] {processor.py:830} INFO - Processing file /opt/airflow/dags/emr_add_step_dag.py for tasks to queue
[2024-03-29T16:40:43.779+0000] {logging_mixin.py:188} INFO - [2024-03-29T16:40:43.779+0000] {dagbag.py:540} INFO - Filling up the DagBag from /opt/airflow/dags/emr_add_step_dag.py
[2024-03-29T16:40:44.060+0000] {logging_mixin.py:188} INFO - [2024-03-29T16:40:44.048+0000] {dagbag.py:350} ERROR - Failed to import: /opt/airflow/dags/emr_add_step_dag.py
Traceback (most recent call last):
  File "/home/airflow/.local/lib/python3.8/site-packages/airflow/models/dagbag.py", line 346, in parse
    loader.exec_module(new_module)
  File "<frozen importlib._bootstrap_external>", line 843, in exec_module
  File "<frozen importlib._bootstrap>", line 219, in _call_with_frames_removed
  File "/opt/airflow/dags/emr_add_step_dag.py", line 52, in <module>
    pipeline = parse_yaml_file(
  File "/opt/airflow/dags/emr_add_step_dag.py", line 48, in parse_yaml_file
    with open(abs_path, 'r') as file:
FileNotFoundError: [Errno 2] No such file or directory: '/mnt/e/reps/highliner/artifacts/dags/dag_definition_ex1.yaml'
[2024-03-29T16:40:44.061+0000] {processor.py:842} WARNING - No viable dags retrieved from /opt/airflow/dags/emr_add_step_dag.py
[2024-03-29T16:40:44.077+0000] {processor.py:183} INFO - Processing /opt/airflow/dags/emr_add_step_dag.py took 0.302 seconds
[2024-03-29T16:41:15.025+0000] {processor.py:161} INFO - Started process (PID=80) to work on /opt/airflow/dags/emr_add_step_dag.py
[2024-03-29T16:41:15.026+0000] {processor.py:830} INFO - Processing file /opt/airflow/dags/emr_add_step_dag.py for tasks to queue
[2024-03-29T16:41:15.028+0000] {logging_mixin.py:188} INFO - [2024-03-29T16:41:15.028+0000] {dagbag.py:540} INFO - Filling up the DagBag from /opt/airflow/dags/emr_add_step_dag.py
[2024-03-29T16:41:15.153+0000] {logging_mixin.py:188} INFO - [2024-03-29T16:41:15.151+0000] {dagbag.py:350} ERROR - Failed to import: /opt/airflow/dags/emr_add_step_dag.py
Traceback (most recent call last):
  File "/home/airflow/.local/lib/python3.8/site-packages/airflow/models/dagbag.py", line 346, in parse
    loader.exec_module(new_module)
  File "<frozen importlib._bootstrap_external>", line 843, in exec_module
  File "<frozen importlib._bootstrap>", line 219, in _call_with_frames_removed
  File "/opt/airflow/dags/emr_add_step_dag.py", line 52, in <module>
    pipeline = parse_yaml_file(
  File "/opt/airflow/dags/emr_add_step_dag.py", line 48, in parse_yaml_file
    with open(abs_path, 'r') as file:
FileNotFoundError: [Errno 2] No such file or directory: '/mnt/e/reps/highliner/artifacts/dags/dag_definition_ex1.yaml'
[2024-03-29T16:41:15.154+0000] {processor.py:842} WARNING - No viable dags retrieved from /opt/airflow/dags/emr_add_step_dag.py
[2024-03-29T16:41:15.177+0000] {processor.py:183} INFO - Processing /opt/airflow/dags/emr_add_step_dag.py took 0.155 seconds
[2024-03-29T16:46:34.207+0000] {processor.py:161} INFO - Started process (PID=40) to work on /opt/airflow/dags/emr_add_step_dag.py
[2024-03-29T16:46:34.208+0000] {processor.py:830} INFO - Processing file /opt/airflow/dags/emr_add_step_dag.py for tasks to queue
[2024-03-29T16:46:34.210+0000] {logging_mixin.py:188} INFO - [2024-03-29T16:46:34.210+0000] {dagbag.py:540} INFO - Filling up the DagBag from /opt/airflow/dags/emr_add_step_dag.py
[2024-03-29T16:46:35.243+0000] {logging_mixin.py:188} INFO - [2024-03-29T16:46:35.240+0000] {dagbag.py:350} ERROR - Failed to import: /opt/airflow/dags/emr_add_step_dag.py
Traceback (most recent call last):
  File "/home/airflow/.local/lib/python3.8/site-packages/dagfactory/dagfactory.py", line 72, in _load_config
    stream=open(config_filepath, "r", encoding="utf-8"),
FileNotFoundError: [Errno 2] No such file or directory: '/opt/airflow/yaml-config/dag_definition_ex1.yaml'

The above exception was the direct cause of the following exception:

Traceback (most recent call last):
  File "/home/airflow/.local/lib/python3.8/site-packages/airflow/models/dagbag.py", line 346, in parse
    loader.exec_module(new_module)
  File "<frozen importlib._bootstrap_external>", line 843, in exec_module
  File "<frozen importlib._bootstrap>", line 219, in _call_with_frames_removed
  File "/opt/airflow/dags/emr_add_step_dag.py", line 45, in <module>
    dag_factory = dagfactory.DagFactory(
  File "/home/airflow/.local/lib/python3.8/site-packages/dagfactory/dagfactory.py", line 39, in __init__
    self.config: Dict[str, Any] = DagFactory._load_config(
  File "/home/airflow/.local/lib/python3.8/site-packages/dagfactory/dagfactory.py", line 76, in _load_config
    raise DagFactoryConfigException("Invalid DAG Factory config file") from err
dagfactory.exceptions.DagFactoryConfigException: Invalid DAG Factory config file
[2024-03-29T16:46:35.244+0000] {processor.py:842} WARNING - No viable dags retrieved from /opt/airflow/dags/emr_add_step_dag.py
[2024-03-29T16:46:35.260+0000] {processor.py:183} INFO - Processing /opt/airflow/dags/emr_add_step_dag.py took 1.056 seconds
[2024-03-29T16:47:05.984+0000] {processor.py:161} INFO - Started process (PID=49) to work on /opt/airflow/dags/emr_add_step_dag.py
[2024-03-29T16:47:05.985+0000] {processor.py:830} INFO - Processing file /opt/airflow/dags/emr_add_step_dag.py for tasks to queue
[2024-03-29T16:47:05.987+0000] {logging_mixin.py:188} INFO - [2024-03-29T16:47:05.986+0000] {dagbag.py:540} INFO - Filling up the DagBag from /opt/airflow/dags/emr_add_step_dag.py
[2024-03-29T16:47:06.222+0000] {logging_mixin.py:188} INFO - [2024-03-29T16:47:06.219+0000] {dagbag.py:350} ERROR - Failed to import: /opt/airflow/dags/emr_add_step_dag.py
Traceback (most recent call last):
  File "/home/airflow/.local/lib/python3.8/site-packages/dagfactory/dagfactory.py", line 72, in _load_config
    stream=open(config_filepath, "r", encoding="utf-8"),
FileNotFoundError: [Errno 2] No such file or directory: '/opt/airflow/yaml-config/dag_definition_ex1.yaml'

The above exception was the direct cause of the following exception:

Traceback (most recent call last):
  File "/home/airflow/.local/lib/python3.8/site-packages/airflow/models/dagbag.py", line 346, in parse
    loader.exec_module(new_module)
  File "<frozen importlib._bootstrap_external>", line 843, in exec_module
  File "<frozen importlib._bootstrap>", line 219, in _call_with_frames_removed
  File "/opt/airflow/dags/emr_add_step_dag.py", line 45, in <module>
    dag_factory = dagfactory.DagFactory(
  File "/home/airflow/.local/lib/python3.8/site-packages/dagfactory/dagfactory.py", line 39, in __init__
    self.config: Dict[str, Any] = DagFactory._load_config(
  File "/home/airflow/.local/lib/python3.8/site-packages/dagfactory/dagfactory.py", line 76, in _load_config
    raise DagFactoryConfigException("Invalid DAG Factory config file") from err
dagfactory.exceptions.DagFactoryConfigException: Invalid DAG Factory config file
[2024-03-29T16:47:06.222+0000] {processor.py:842} WARNING - No viable dags retrieved from /opt/airflow/dags/emr_add_step_dag.py
[2024-03-29T16:47:06.242+0000] {processor.py:183} INFO - Processing /opt/airflow/dags/emr_add_step_dag.py took 0.260 seconds
[2024-03-29T16:47:36.280+0000] {processor.py:161} INFO - Started process (PID=57) to work on /opt/airflow/dags/emr_add_step_dag.py
[2024-03-29T16:47:36.280+0000] {processor.py:830} INFO - Processing file /opt/airflow/dags/emr_add_step_dag.py for tasks to queue
[2024-03-29T16:47:36.282+0000] {logging_mixin.py:188} INFO - [2024-03-29T16:47:36.282+0000] {dagbag.py:540} INFO - Filling up the DagBag from /opt/airflow/dags/emr_add_step_dag.py
[2024-03-29T16:47:36.520+0000] {logging_mixin.py:188} INFO - [2024-03-29T16:47:36.518+0000] {dagbag.py:350} ERROR - Failed to import: /opt/airflow/dags/emr_add_step_dag.py
Traceback (most recent call last):
  File "/home/airflow/.local/lib/python3.8/site-packages/dagfactory/dagfactory.py", line 72, in _load_config
    stream=open(config_filepath, "r", encoding="utf-8"),
FileNotFoundError: [Errno 2] No such file or directory: '/opt/airflow/yaml-config/dag_definition_ex1.yaml'

The above exception was the direct cause of the following exception:

Traceback (most recent call last):
  File "/home/airflow/.local/lib/python3.8/site-packages/airflow/models/dagbag.py", line 346, in parse
    loader.exec_module(new_module)
  File "<frozen importlib._bootstrap_external>", line 843, in exec_module
  File "<frozen importlib._bootstrap>", line 219, in _call_with_frames_removed
  File "/opt/airflow/dags/emr_add_step_dag.py", line 45, in <module>
    dag_factory = dagfactory.DagFactory(
  File "/home/airflow/.local/lib/python3.8/site-packages/dagfactory/dagfactory.py", line 39, in __init__
    self.config: Dict[str, Any] = DagFactory._load_config(
  File "/home/airflow/.local/lib/python3.8/site-packages/dagfactory/dagfactory.py", line 76, in _load_config
    raise DagFactoryConfigException("Invalid DAG Factory config file") from err
dagfactory.exceptions.DagFactoryConfigException: Invalid DAG Factory config file
[2024-03-29T16:47:36.520+0000] {processor.py:842} WARNING - No viable dags retrieved from /opt/airflow/dags/emr_add_step_dag.py
[2024-03-29T16:47:36.540+0000] {processor.py:183} INFO - Processing /opt/airflow/dags/emr_add_step_dag.py took 0.263 seconds
[2024-03-29T16:48:06.644+0000] {processor.py:161} INFO - Started process (PID=65) to work on /opt/airflow/dags/emr_add_step_dag.py
[2024-03-29T16:48:06.645+0000] {processor.py:830} INFO - Processing file /opt/airflow/dags/emr_add_step_dag.py for tasks to queue
[2024-03-29T16:48:06.647+0000] {logging_mixin.py:188} INFO - [2024-03-29T16:48:06.646+0000] {dagbag.py:540} INFO - Filling up the DagBag from /opt/airflow/dags/emr_add_step_dag.py
[2024-03-29T16:48:06.890+0000] {logging_mixin.py:188} INFO - [2024-03-29T16:48:06.886+0000] {dagbag.py:350} ERROR - Failed to import: /opt/airflow/dags/emr_add_step_dag.py
Traceback (most recent call last):
  File "/home/airflow/.local/lib/python3.8/site-packages/dagfactory/dagfactory.py", line 72, in _load_config
    stream=open(config_filepath, "r", encoding="utf-8"),
FileNotFoundError: [Errno 2] No such file or directory: '/opt/airflow/yaml-config/dag_definition_ex1.yaml'

The above exception was the direct cause of the following exception:

Traceback (most recent call last):
  File "/home/airflow/.local/lib/python3.8/site-packages/airflow/models/dagbag.py", line 346, in parse
    loader.exec_module(new_module)
  File "<frozen importlib._bootstrap_external>", line 843, in exec_module
  File "<frozen importlib._bootstrap>", line 219, in _call_with_frames_removed
  File "/opt/airflow/dags/emr_add_step_dag.py", line 45, in <module>
    dag_factory = dagfactory.DagFactory(
  File "/home/airflow/.local/lib/python3.8/site-packages/dagfactory/dagfactory.py", line 39, in __init__
    self.config: Dict[str, Any] = DagFactory._load_config(
  File "/home/airflow/.local/lib/python3.8/site-packages/dagfactory/dagfactory.py", line 76, in _load_config
    raise DagFactoryConfigException("Invalid DAG Factory config file") from err
dagfactory.exceptions.DagFactoryConfigException: Invalid DAG Factory config file
[2024-03-29T16:48:06.891+0000] {processor.py:842} WARNING - No viable dags retrieved from /opt/airflow/dags/emr_add_step_dag.py
[2024-03-29T16:48:06.905+0000] {processor.py:183} INFO - Processing /opt/airflow/dags/emr_add_step_dag.py took 0.264 seconds
[2024-03-29T16:48:36.982+0000] {processor.py:161} INFO - Started process (PID=73) to work on /opt/airflow/dags/emr_add_step_dag.py
[2024-03-29T16:48:36.983+0000] {processor.py:830} INFO - Processing file /opt/airflow/dags/emr_add_step_dag.py for tasks to queue
[2024-03-29T16:48:36.984+0000] {logging_mixin.py:188} INFO - [2024-03-29T16:48:36.984+0000] {dagbag.py:540} INFO - Filling up the DagBag from /opt/airflow/dags/emr_add_step_dag.py
[2024-03-29T16:48:37.199+0000] {logging_mixin.py:188} INFO - [2024-03-29T16:48:37.197+0000] {dagbag.py:350} ERROR - Failed to import: /opt/airflow/dags/emr_add_step_dag.py
Traceback (most recent call last):
  File "/home/airflow/.local/lib/python3.8/site-packages/dagfactory/dagfactory.py", line 72, in _load_config
    stream=open(config_filepath, "r", encoding="utf-8"),
FileNotFoundError: [Errno 2] No such file or directory: '/opt/airflow/yaml-config/dag_definition_ex1.yaml'

The above exception was the direct cause of the following exception:

Traceback (most recent call last):
  File "/home/airflow/.local/lib/python3.8/site-packages/airflow/models/dagbag.py", line 346, in parse
    loader.exec_module(new_module)
  File "<frozen importlib._bootstrap_external>", line 843, in exec_module
  File "<frozen importlib._bootstrap>", line 219, in _call_with_frames_removed
  File "/opt/airflow/dags/emr_add_step_dag.py", line 45, in <module>
    dag_factory = dagfactory.DagFactory(
  File "/home/airflow/.local/lib/python3.8/site-packages/dagfactory/dagfactory.py", line 39, in __init__
    self.config: Dict[str, Any] = DagFactory._load_config(
  File "/home/airflow/.local/lib/python3.8/site-packages/dagfactory/dagfactory.py", line 76, in _load_config
    raise DagFactoryConfigException("Invalid DAG Factory config file") from err
dagfactory.exceptions.DagFactoryConfigException: Invalid DAG Factory config file
[2024-03-29T16:48:37.199+0000] {processor.py:842} WARNING - No viable dags retrieved from /opt/airflow/dags/emr_add_step_dag.py
[2024-03-29T16:48:37.212+0000] {processor.py:183} INFO - Processing /opt/airflow/dags/emr_add_step_dag.py took 0.233 seconds
[2024-03-29T16:49:07.266+0000] {processor.py:161} INFO - Started process (PID=81) to work on /opt/airflow/dags/emr_add_step_dag.py
[2024-03-29T16:49:07.266+0000] {processor.py:830} INFO - Processing file /opt/airflow/dags/emr_add_step_dag.py for tasks to queue
[2024-03-29T16:49:07.268+0000] {logging_mixin.py:188} INFO - [2024-03-29T16:49:07.268+0000] {dagbag.py:540} INFO - Filling up the DagBag from /opt/airflow/dags/emr_add_step_dag.py
[2024-03-29T16:49:07.390+0000] {logging_mixin.py:188} INFO - [2024-03-29T16:49:07.388+0000] {dagbag.py:350} ERROR - Failed to import: /opt/airflow/dags/emr_add_step_dag.py
Traceback (most recent call last):
  File "/home/airflow/.local/lib/python3.8/site-packages/dagfactory/dagfactory.py", line 72, in _load_config
    stream=open(config_filepath, "r", encoding="utf-8"),
FileNotFoundError: [Errno 2] No such file or directory: '/opt/airflow/yaml-config/dag_definition_ex1.yaml'

The above exception was the direct cause of the following exception:

Traceback (most recent call last):
  File "/home/airflow/.local/lib/python3.8/site-packages/airflow/models/dagbag.py", line 346, in parse
    loader.exec_module(new_module)
  File "<frozen importlib._bootstrap_external>", line 843, in exec_module
  File "<frozen importlib._bootstrap>", line 219, in _call_with_frames_removed
  File "/opt/airflow/dags/emr_add_step_dag.py", line 45, in <module>
    dag_factory = dagfactory.DagFactory(
  File "/home/airflow/.local/lib/python3.8/site-packages/dagfactory/dagfactory.py", line 39, in __init__
    self.config: Dict[str, Any] = DagFactory._load_config(
  File "/home/airflow/.local/lib/python3.8/site-packages/dagfactory/dagfactory.py", line 76, in _load_config
    raise DagFactoryConfigException("Invalid DAG Factory config file") from err
dagfactory.exceptions.DagFactoryConfigException: Invalid DAG Factory config file
[2024-03-29T16:49:07.391+0000] {processor.py:842} WARNING - No viable dags retrieved from /opt/airflow/dags/emr_add_step_dag.py
[2024-03-29T16:49:07.413+0000] {processor.py:183} INFO - Processing /opt/airflow/dags/emr_add_step_dag.py took 0.150 seconds
[2024-03-29T16:50:37.661+0000] {processor.py:161} INFO - Started process (PID=38) to work on /opt/airflow/dags/emr_add_step_dag.py
[2024-03-29T16:50:37.662+0000] {processor.py:830} INFO - Processing file /opt/airflow/dags/emr_add_step_dag.py for tasks to queue
[2024-03-29T16:50:37.663+0000] {logging_mixin.py:188} INFO - [2024-03-29T16:50:37.663+0000] {dagbag.py:540} INFO - Filling up the DagBag from /opt/airflow/dags/emr_add_step_dag.py
[2024-03-29T16:50:37.849+0000] {logging_mixin.py:188} INFO - [2024-03-29T16:50:37.846+0000] {dagbag.py:350} ERROR - Failed to import: /opt/airflow/dags/emr_add_step_dag.py
Traceback (most recent call last):
  File "/home/airflow/.local/lib/python3.8/site-packages/dagfactory/dagfactory.py", line 72, in _load_config
    stream=open(config_filepath, "r", encoding="utf-8"),
FileNotFoundError: [Errno 2] No such file or directory: '/opt/airflow/yaml-config/dag_definition_ex1.yaml'

The above exception was the direct cause of the following exception:

Traceback (most recent call last):
  File "/home/airflow/.local/lib/python3.8/site-packages/airflow/models/dagbag.py", line 346, in parse
    loader.exec_module(new_module)
  File "<frozen importlib._bootstrap_external>", line 843, in exec_module
  File "<frozen importlib._bootstrap>", line 219, in _call_with_frames_removed
  File "/opt/airflow/dags/emr_add_step_dag.py", line 45, in <module>
    dag_factory = dagfactory.DagFactory(
  File "/home/airflow/.local/lib/python3.8/site-packages/dagfactory/dagfactory.py", line 39, in __init__
    self.config: Dict[str, Any] = DagFactory._load_config(
  File "/home/airflow/.local/lib/python3.8/site-packages/dagfactory/dagfactory.py", line 76, in _load_config
    raise DagFactoryConfigException("Invalid DAG Factory config file") from err
dagfactory.exceptions.DagFactoryConfigException: Invalid DAG Factory config file
[2024-03-29T16:50:37.849+0000] {processor.py:842} WARNING - No viable dags retrieved from /opt/airflow/dags/emr_add_step_dag.py
[2024-03-29T16:50:37.875+0000] {processor.py:183} INFO - Processing /opt/airflow/dags/emr_add_step_dag.py took 0.217 seconds
[2024-03-29T16:51:08.139+0000] {processor.py:161} INFO - Started process (PID=46) to work on /opt/airflow/dags/emr_add_step_dag.py
[2024-03-29T16:51:08.140+0000] {processor.py:830} INFO - Processing file /opt/airflow/dags/emr_add_step_dag.py for tasks to queue
[2024-03-29T16:51:08.142+0000] {logging_mixin.py:188} INFO - [2024-03-29T16:51:08.141+0000] {dagbag.py:540} INFO - Filling up the DagBag from /opt/airflow/dags/emr_add_step_dag.py
[2024-03-29T16:51:08.272+0000] {logging_mixin.py:188} INFO - [2024-03-29T16:51:08.270+0000] {dagbag.py:350} ERROR - Failed to import: /opt/airflow/dags/emr_add_step_dag.py
Traceback (most recent call last):
  File "/home/airflow/.local/lib/python3.8/site-packages/dagfactory/dagfactory.py", line 72, in _load_config
    stream=open(config_filepath, "r", encoding="utf-8"),
FileNotFoundError: [Errno 2] No such file or directory: '/opt/airflow/yaml-config/dag_definition_ex1.yaml'

The above exception was the direct cause of the following exception:

Traceback (most recent call last):
  File "/home/airflow/.local/lib/python3.8/site-packages/airflow/models/dagbag.py", line 346, in parse
    loader.exec_module(new_module)
  File "<frozen importlib._bootstrap_external>", line 843, in exec_module
  File "<frozen importlib._bootstrap>", line 219, in _call_with_frames_removed
  File "/opt/airflow/dags/emr_add_step_dag.py", line 45, in <module>
    dag_factory = dagfactory.DagFactory(
  File "/home/airflow/.local/lib/python3.8/site-packages/dagfactory/dagfactory.py", line 39, in __init__
    self.config: Dict[str, Any] = DagFactory._load_config(
  File "/home/airflow/.local/lib/python3.8/site-packages/dagfactory/dagfactory.py", line 76, in _load_config
    raise DagFactoryConfigException("Invalid DAG Factory config file") from err
dagfactory.exceptions.DagFactoryConfigException: Invalid DAG Factory config file
[2024-03-29T16:51:08.272+0000] {processor.py:842} WARNING - No viable dags retrieved from /opt/airflow/dags/emr_add_step_dag.py
[2024-03-29T16:51:08.293+0000] {processor.py:183} INFO - Processing /opt/airflow/dags/emr_add_step_dag.py took 0.157 seconds
[2024-03-29T16:51:38.439+0000] {processor.py:161} INFO - Started process (PID=54) to work on /opt/airflow/dags/emr_add_step_dag.py
[2024-03-29T16:51:38.440+0000] {processor.py:830} INFO - Processing file /opt/airflow/dags/emr_add_step_dag.py for tasks to queue
[2024-03-29T16:51:38.442+0000] {logging_mixin.py:188} INFO - [2024-03-29T16:51:38.442+0000] {dagbag.py:540} INFO - Filling up the DagBag from /opt/airflow/dags/emr_add_step_dag.py
[2024-03-29T16:51:38.568+0000] {logging_mixin.py:188} INFO - [2024-03-29T16:51:38.565+0000] {dagbag.py:350} ERROR - Failed to import: /opt/airflow/dags/emr_add_step_dag.py
Traceback (most recent call last):
  File "/home/airflow/.local/lib/python3.8/site-packages/dagfactory/dagfactory.py", line 72, in _load_config
    stream=open(config_filepath, "r", encoding="utf-8"),
FileNotFoundError: [Errno 2] No such file or directory: '/opt/airflow/yaml-config/dag_definition_ex1.yaml'

The above exception was the direct cause of the following exception:

Traceback (most recent call last):
  File "/home/airflow/.local/lib/python3.8/site-packages/airflow/models/dagbag.py", line 346, in parse
    loader.exec_module(new_module)
  File "<frozen importlib._bootstrap_external>", line 843, in exec_module
  File "<frozen importlib._bootstrap>", line 219, in _call_with_frames_removed
  File "/opt/airflow/dags/emr_add_step_dag.py", line 45, in <module>
    dag_factory = dagfactory.DagFactory(
  File "/home/airflow/.local/lib/python3.8/site-packages/dagfactory/dagfactory.py", line 39, in __init__
    self.config: Dict[str, Any] = DagFactory._load_config(
  File "/home/airflow/.local/lib/python3.8/site-packages/dagfactory/dagfactory.py", line 76, in _load_config
    raise DagFactoryConfigException("Invalid DAG Factory config file") from err
dagfactory.exceptions.DagFactoryConfigException: Invalid DAG Factory config file
[2024-03-29T16:51:38.568+0000] {processor.py:842} WARNING - No viable dags retrieved from /opt/airflow/dags/emr_add_step_dag.py
[2024-03-29T16:51:38.591+0000] {processor.py:183} INFO - Processing /opt/airflow/dags/emr_add_step_dag.py took 0.154 seconds
[2024-03-29T16:52:08.808+0000] {processor.py:161} INFO - Started process (PID=62) to work on /opt/airflow/dags/emr_add_step_dag.py
[2024-03-29T16:52:08.809+0000] {processor.py:830} INFO - Processing file /opt/airflow/dags/emr_add_step_dag.py for tasks to queue
[2024-03-29T16:52:08.811+0000] {logging_mixin.py:188} INFO - [2024-03-29T16:52:08.811+0000] {dagbag.py:540} INFO - Filling up the DagBag from /opt/airflow/dags/emr_add_step_dag.py
[2024-03-29T16:52:08.936+0000] {logging_mixin.py:188} INFO - [2024-03-29T16:52:08.934+0000] {dagbag.py:350} ERROR - Failed to import: /opt/airflow/dags/emr_add_step_dag.py
Traceback (most recent call last):
  File "/home/airflow/.local/lib/python3.8/site-packages/dagfactory/dagfactory.py", line 72, in _load_config
    stream=open(config_filepath, "r", encoding="utf-8"),
FileNotFoundError: [Errno 2] No such file or directory: '/opt/airflow/yaml-config/dag_definition_ex1.yaml'

The above exception was the direct cause of the following exception:

Traceback (most recent call last):
  File "/home/airflow/.local/lib/python3.8/site-packages/airflow/models/dagbag.py", line 346, in parse
    loader.exec_module(new_module)
  File "<frozen importlib._bootstrap_external>", line 843, in exec_module
  File "<frozen importlib._bootstrap>", line 219, in _call_with_frames_removed
  File "/opt/airflow/dags/emr_add_step_dag.py", line 45, in <module>
    dag_factory = dagfactory.DagFactory(
  File "/home/airflow/.local/lib/python3.8/site-packages/dagfactory/dagfactory.py", line 39, in __init__
    self.config: Dict[str, Any] = DagFactory._load_config(
  File "/home/airflow/.local/lib/python3.8/site-packages/dagfactory/dagfactory.py", line 76, in _load_config
    raise DagFactoryConfigException("Invalid DAG Factory config file") from err
dagfactory.exceptions.DagFactoryConfigException: Invalid DAG Factory config file
[2024-03-29T16:52:08.937+0000] {processor.py:842} WARNING - No viable dags retrieved from /opt/airflow/dags/emr_add_step_dag.py
[2024-03-29T16:52:08.958+0000] {processor.py:183} INFO - Processing /opt/airflow/dags/emr_add_step_dag.py took 0.152 seconds
[2024-03-29T16:52:39.146+0000] {processor.py:161} INFO - Started process (PID=70) to work on /opt/airflow/dags/emr_add_step_dag.py
[2024-03-29T16:52:39.146+0000] {processor.py:830} INFO - Processing file /opt/airflow/dags/emr_add_step_dag.py for tasks to queue
[2024-03-29T16:52:39.148+0000] {logging_mixin.py:188} INFO - [2024-03-29T16:52:39.148+0000] {dagbag.py:540} INFO - Filling up the DagBag from /opt/airflow/dags/emr_add_step_dag.py
[2024-03-29T16:52:39.277+0000] {logging_mixin.py:188} INFO - [2024-03-29T16:52:39.275+0000] {dagbag.py:350} ERROR - Failed to import: /opt/airflow/dags/emr_add_step_dag.py
Traceback (most recent call last):
  File "/home/airflow/.local/lib/python3.8/site-packages/dagfactory/dagfactory.py", line 72, in _load_config
    stream=open(config_filepath, "r", encoding="utf-8"),
FileNotFoundError: [Errno 2] No such file or directory: '/opt/airflow/yaml-config/dag_definition_ex1.yaml'

The above exception was the direct cause of the following exception:

Traceback (most recent call last):
  File "/home/airflow/.local/lib/python3.8/site-packages/airflow/models/dagbag.py", line 346, in parse
    loader.exec_module(new_module)
  File "<frozen importlib._bootstrap_external>", line 843, in exec_module
  File "<frozen importlib._bootstrap>", line 219, in _call_with_frames_removed
  File "/opt/airflow/dags/emr_add_step_dag.py", line 45, in <module>
    dag_factory = dagfactory.DagFactory(
  File "/home/airflow/.local/lib/python3.8/site-packages/dagfactory/dagfactory.py", line 39, in __init__
    self.config: Dict[str, Any] = DagFactory._load_config(
  File "/home/airflow/.local/lib/python3.8/site-packages/dagfactory/dagfactory.py", line 76, in _load_config
    raise DagFactoryConfigException("Invalid DAG Factory config file") from err
dagfactory.exceptions.DagFactoryConfigException: Invalid DAG Factory config file
[2024-03-29T16:52:39.277+0000] {processor.py:842} WARNING - No viable dags retrieved from /opt/airflow/dags/emr_add_step_dag.py
[2024-03-29T16:52:39.291+0000] {processor.py:183} INFO - Processing /opt/airflow/dags/emr_add_step_dag.py took 0.148 seconds
[2024-03-29T16:53:09.465+0000] {processor.py:161} INFO - Started process (PID=78) to work on /opt/airflow/dags/emr_add_step_dag.py
[2024-03-29T16:53:09.466+0000] {processor.py:830} INFO - Processing file /opt/airflow/dags/emr_add_step_dag.py for tasks to queue
[2024-03-29T16:53:09.467+0000] {logging_mixin.py:188} INFO - [2024-03-29T16:53:09.467+0000] {dagbag.py:540} INFO - Filling up the DagBag from /opt/airflow/dags/emr_add_step_dag.py
[2024-03-29T16:53:09.594+0000] {logging_mixin.py:188} INFO - [2024-03-29T16:53:09.592+0000] {dagbag.py:350} ERROR - Failed to import: /opt/airflow/dags/emr_add_step_dag.py
Traceback (most recent call last):
  File "/home/airflow/.local/lib/python3.8/site-packages/dagfactory/dagfactory.py", line 72, in _load_config
    stream=open(config_filepath, "r", encoding="utf-8"),
FileNotFoundError: [Errno 2] No such file or directory: '/opt/airflow/yaml-config/dag_definition_ex1.yaml'

The above exception was the direct cause of the following exception:

Traceback (most recent call last):
  File "/home/airflow/.local/lib/python3.8/site-packages/airflow/models/dagbag.py", line 346, in parse
    loader.exec_module(new_module)
  File "<frozen importlib._bootstrap_external>", line 843, in exec_module
  File "<frozen importlib._bootstrap>", line 219, in _call_with_frames_removed
  File "/opt/airflow/dags/emr_add_step_dag.py", line 45, in <module>
    dag_factory = dagfactory.DagFactory(
  File "/home/airflow/.local/lib/python3.8/site-packages/dagfactory/dagfactory.py", line 39, in __init__
    self.config: Dict[str, Any] = DagFactory._load_config(
  File "/home/airflow/.local/lib/python3.8/site-packages/dagfactory/dagfactory.py", line 76, in _load_config
    raise DagFactoryConfigException("Invalid DAG Factory config file") from err
dagfactory.exceptions.DagFactoryConfigException: Invalid DAG Factory config file
[2024-03-29T16:53:09.594+0000] {processor.py:842} WARNING - No viable dags retrieved from /opt/airflow/dags/emr_add_step_dag.py
[2024-03-29T16:53:09.619+0000] {processor.py:183} INFO - Processing /opt/airflow/dags/emr_add_step_dag.py took 0.158 seconds
[2024-03-29T16:53:39.770+0000] {processor.py:161} INFO - Started process (PID=86) to work on /opt/airflow/dags/emr_add_step_dag.py
[2024-03-29T16:53:39.771+0000] {processor.py:830} INFO - Processing file /opt/airflow/dags/emr_add_step_dag.py for tasks to queue
[2024-03-29T16:53:39.774+0000] {logging_mixin.py:188} INFO - [2024-03-29T16:53:39.773+0000] {dagbag.py:540} INFO - Filling up the DagBag from /opt/airflow/dags/emr_add_step_dag.py
[2024-03-29T16:53:39.938+0000] {logging_mixin.py:188} INFO - [2024-03-29T16:53:39.935+0000] {dagbag.py:350} ERROR - Failed to import: /opt/airflow/dags/emr_add_step_dag.py
Traceback (most recent call last):
  File "/home/airflow/.local/lib/python3.8/site-packages/dagfactory/dagfactory.py", line 72, in _load_config
    stream=open(config_filepath, "r", encoding="utf-8"),
FileNotFoundError: [Errno 2] No such file or directory: '/opt/airflow/yaml-config/dag_definition_ex1.yaml'

The above exception was the direct cause of the following exception:

Traceback (most recent call last):
  File "/home/airflow/.local/lib/python3.8/site-packages/airflow/models/dagbag.py", line 346, in parse
    loader.exec_module(new_module)
  File "<frozen importlib._bootstrap_external>", line 843, in exec_module
  File "<frozen importlib._bootstrap>", line 219, in _call_with_frames_removed
  File "/opt/airflow/dags/emr_add_step_dag.py", line 45, in <module>
    dag_factory = dagfactory.DagFactory(
  File "/home/airflow/.local/lib/python3.8/site-packages/dagfactory/dagfactory.py", line 39, in __init__
    self.config: Dict[str, Any] = DagFactory._load_config(
  File "/home/airflow/.local/lib/python3.8/site-packages/dagfactory/dagfactory.py", line 76, in _load_config
    raise DagFactoryConfigException("Invalid DAG Factory config file") from err
dagfactory.exceptions.DagFactoryConfigException: Invalid DAG Factory config file
[2024-03-29T16:53:39.939+0000] {processor.py:842} WARNING - No viable dags retrieved from /opt/airflow/dags/emr_add_step_dag.py
[2024-03-29T16:53:39.962+0000] {processor.py:183} INFO - Processing /opt/airflow/dags/emr_add_step_dag.py took 0.196 seconds
[2024-03-29T16:54:10.106+0000] {processor.py:161} INFO - Started process (PID=94) to work on /opt/airflow/dags/emr_add_step_dag.py
[2024-03-29T16:54:10.116+0000] {processor.py:830} INFO - Processing file /opt/airflow/dags/emr_add_step_dag.py for tasks to queue
[2024-03-29T16:54:10.120+0000] {logging_mixin.py:188} INFO - [2024-03-29T16:54:10.120+0000] {dagbag.py:540} INFO - Filling up the DagBag from /opt/airflow/dags/emr_add_step_dag.py
[2024-03-29T16:54:10.481+0000] {logging_mixin.py:188} INFO - [2024-03-29T16:54:10.477+0000] {dagbag.py:350} ERROR - Failed to import: /opt/airflow/dags/emr_add_step_dag.py
Traceback (most recent call last):
  File "/home/airflow/.local/lib/python3.8/site-packages/dagfactory/dagfactory.py", line 72, in _load_config
    stream=open(config_filepath, "r", encoding="utf-8"),
FileNotFoundError: [Errno 2] No such file or directory: '/opt/airflow/yaml-config/dag_definition_ex1.yaml'

The above exception was the direct cause of the following exception:

Traceback (most recent call last):
  File "/home/airflow/.local/lib/python3.8/site-packages/airflow/models/dagbag.py", line 346, in parse
    loader.exec_module(new_module)
  File "<frozen importlib._bootstrap_external>", line 843, in exec_module
  File "<frozen importlib._bootstrap>", line 219, in _call_with_frames_removed
  File "/opt/airflow/dags/emr_add_step_dag.py", line 45, in <module>
    dag_factory = dagfactory.DagFactory(
  File "/home/airflow/.local/lib/python3.8/site-packages/dagfactory/dagfactory.py", line 39, in __init__
    self.config: Dict[str, Any] = DagFactory._load_config(
  File "/home/airflow/.local/lib/python3.8/site-packages/dagfactory/dagfactory.py", line 76, in _load_config
    raise DagFactoryConfigException("Invalid DAG Factory config file") from err
dagfactory.exceptions.DagFactoryConfigException: Invalid DAG Factory config file
[2024-03-29T16:54:10.481+0000] {processor.py:842} WARNING - No viable dags retrieved from /opt/airflow/dags/emr_add_step_dag.py
[2024-03-29T16:54:10.503+0000] {processor.py:183} INFO - Processing /opt/airflow/dags/emr_add_step_dag.py took 0.400 seconds
[2024-03-29T16:54:40.597+0000] {processor.py:161} INFO - Started process (PID=103) to work on /opt/airflow/dags/emr_add_step_dag.py
[2024-03-29T16:54:40.598+0000] {processor.py:830} INFO - Processing file /opt/airflow/dags/emr_add_step_dag.py for tasks to queue
[2024-03-29T16:54:40.599+0000] {logging_mixin.py:188} INFO - [2024-03-29T16:54:40.599+0000] {dagbag.py:540} INFO - Filling up the DagBag from /opt/airflow/dags/emr_add_step_dag.py
[2024-03-29T16:54:40.745+0000] {logging_mixin.py:188} INFO - [2024-03-29T16:54:40.742+0000] {dagbag.py:350} ERROR - Failed to import: /opt/airflow/dags/emr_add_step_dag.py
Traceback (most recent call last):
  File "/home/airflow/.local/lib/python3.8/site-packages/dagfactory/dagfactory.py", line 72, in _load_config
    stream=open(config_filepath, "r", encoding="utf-8"),
FileNotFoundError: [Errno 2] No such file or directory: '/opt/airflow/yaml-config/dag_definition_ex1.yaml'

The above exception was the direct cause of the following exception:

Traceback (most recent call last):
  File "/home/airflow/.local/lib/python3.8/site-packages/airflow/models/dagbag.py", line 346, in parse
    loader.exec_module(new_module)
  File "<frozen importlib._bootstrap_external>", line 843, in exec_module
  File "<frozen importlib._bootstrap>", line 219, in _call_with_frames_removed
  File "/opt/airflow/dags/emr_add_step_dag.py", line 45, in <module>
    dag_factory = dagfactory.DagFactory(
  File "/home/airflow/.local/lib/python3.8/site-packages/dagfactory/dagfactory.py", line 39, in __init__
    self.config: Dict[str, Any] = DagFactory._load_config(
  File "/home/airflow/.local/lib/python3.8/site-packages/dagfactory/dagfactory.py", line 76, in _load_config
    raise DagFactoryConfigException("Invalid DAG Factory config file") from err
dagfactory.exceptions.DagFactoryConfigException: Invalid DAG Factory config file
[2024-03-29T16:54:40.745+0000] {processor.py:842} WARNING - No viable dags retrieved from /opt/airflow/dags/emr_add_step_dag.py
[2024-03-29T16:54:40.762+0000] {processor.py:183} INFO - Processing /opt/airflow/dags/emr_add_step_dag.py took 0.168 seconds
[2024-03-29T16:55:10.861+0000] {processor.py:161} INFO - Started process (PID=111) to work on /opt/airflow/dags/emr_add_step_dag.py
[2024-03-29T16:55:10.861+0000] {processor.py:830} INFO - Processing file /opt/airflow/dags/emr_add_step_dag.py for tasks to queue
[2024-03-29T16:55:10.863+0000] {logging_mixin.py:188} INFO - [2024-03-29T16:55:10.863+0000] {dagbag.py:540} INFO - Filling up the DagBag from /opt/airflow/dags/emr_add_step_dag.py
[2024-03-29T16:55:10.982+0000] {logging_mixin.py:188} INFO - [2024-03-29T16:55:10.980+0000] {dagbag.py:350} ERROR - Failed to import: /opt/airflow/dags/emr_add_step_dag.py
Traceback (most recent call last):
  File "/home/airflow/.local/lib/python3.8/site-packages/dagfactory/dagfactory.py", line 72, in _load_config
    stream=open(config_filepath, "r", encoding="utf-8"),
FileNotFoundError: [Errno 2] No such file or directory: '/opt/airflow/yaml-config/dag_definition_ex1.yaml'

The above exception was the direct cause of the following exception:

Traceback (most recent call last):
  File "/home/airflow/.local/lib/python3.8/site-packages/airflow/models/dagbag.py", line 346, in parse
    loader.exec_module(new_module)
  File "<frozen importlib._bootstrap_external>", line 843, in exec_module
  File "<frozen importlib._bootstrap>", line 219, in _call_with_frames_removed
  File "/opt/airflow/dags/emr_add_step_dag.py", line 45, in <module>
    dag_factory = dagfactory.DagFactory(
  File "/home/airflow/.local/lib/python3.8/site-packages/dagfactory/dagfactory.py", line 39, in __init__
    self.config: Dict[str, Any] = DagFactory._load_config(
  File "/home/airflow/.local/lib/python3.8/site-packages/dagfactory/dagfactory.py", line 76, in _load_config
    raise DagFactoryConfigException("Invalid DAG Factory config file") from err
dagfactory.exceptions.DagFactoryConfigException: Invalid DAG Factory config file
[2024-03-29T16:55:10.982+0000] {processor.py:842} WARNING - No viable dags retrieved from /opt/airflow/dags/emr_add_step_dag.py
[2024-03-29T16:55:10.996+0000] {processor.py:183} INFO - Processing /opt/airflow/dags/emr_add_step_dag.py took 0.138 seconds
[2024-03-29T16:56:09.491+0000] {processor.py:161} INFO - Started process (PID=39) to work on /opt/airflow/dags/emr_add_step_dag.py
[2024-03-29T16:56:09.492+0000] {processor.py:830} INFO - Processing file /opt/airflow/dags/emr_add_step_dag.py for tasks to queue
[2024-03-29T16:56:09.493+0000] {logging_mixin.py:188} INFO - [2024-03-29T16:56:09.493+0000] {dagbag.py:540} INFO - Filling up the DagBag from /opt/airflow/dags/emr_add_step_dag.py
[2024-03-29T16:56:10.540+0000] {logging_mixin.py:188} INFO - [2024-03-29T16:56:10.538+0000] {dagbag.py:350} ERROR - Failed to import: /opt/airflow/dags/emr_add_step_dag.py
Traceback (most recent call last):
  File "/home/airflow/.local/lib/python3.8/site-packages/dagfactory/dagfactory.py", line 72, in _load_config
    stream=open(config_filepath, "r", encoding="utf-8"),
FileNotFoundError: [Errno 2] No such file or directory: '/opt/airflow/yaml-config/dag_definition_ex1.yaml'

The above exception was the direct cause of the following exception:

Traceback (most recent call last):
  File "/home/airflow/.local/lib/python3.8/site-packages/airflow/models/dagbag.py", line 346, in parse
    loader.exec_module(new_module)
  File "<frozen importlib._bootstrap_external>", line 843, in exec_module
  File "<frozen importlib._bootstrap>", line 219, in _call_with_frames_removed
  File "/opt/airflow/dags/emr_add_step_dag.py", line 45, in <module>
    dag_factory = dagfactory.DagFactory(
  File "/home/airflow/.local/lib/python3.8/site-packages/dagfactory/dagfactory.py", line 39, in __init__
    self.config: Dict[str, Any] = DagFactory._load_config(
  File "/home/airflow/.local/lib/python3.8/site-packages/dagfactory/dagfactory.py", line 76, in _load_config
    raise DagFactoryConfigException("Invalid DAG Factory config file") from err
dagfactory.exceptions.DagFactoryConfigException: Invalid DAG Factory config file
[2024-03-29T16:56:10.540+0000] {processor.py:842} WARNING - No viable dags retrieved from /opt/airflow/dags/emr_add_step_dag.py
[2024-03-29T16:56:10.558+0000] {processor.py:183} INFO - Processing /opt/airflow/dags/emr_add_step_dag.py took 1.070 seconds
[2024-03-29T16:56:41.318+0000] {processor.py:161} INFO - Started process (PID=48) to work on /opt/airflow/dags/emr_add_step_dag.py
[2024-03-29T16:56:41.319+0000] {processor.py:830} INFO - Processing file /opt/airflow/dags/emr_add_step_dag.py for tasks to queue
[2024-03-29T16:56:41.320+0000] {logging_mixin.py:188} INFO - [2024-03-29T16:56:41.320+0000] {dagbag.py:540} INFO - Filling up the DagBag from /opt/airflow/dags/emr_add_step_dag.py
[2024-03-29T16:56:41.582+0000] {logging_mixin.py:188} INFO - [2024-03-29T16:56:41.579+0000] {dagbag.py:350} ERROR - Failed to import: /opt/airflow/dags/emr_add_step_dag.py
Traceback (most recent call last):
  File "/home/airflow/.local/lib/python3.8/site-packages/dagfactory/dagfactory.py", line 72, in _load_config
    stream=open(config_filepath, "r", encoding="utf-8"),
FileNotFoundError: [Errno 2] No such file or directory: '/opt/airflow/yaml-config/dag_definition_ex1.yaml'

The above exception was the direct cause of the following exception:

Traceback (most recent call last):
  File "/home/airflow/.local/lib/python3.8/site-packages/airflow/models/dagbag.py", line 346, in parse
    loader.exec_module(new_module)
  File "<frozen importlib._bootstrap_external>", line 843, in exec_module
  File "<frozen importlib._bootstrap>", line 219, in _call_with_frames_removed
  File "/opt/airflow/dags/emr_add_step_dag.py", line 45, in <module>
    dag_factory = dagfactory.DagFactory(
  File "/home/airflow/.local/lib/python3.8/site-packages/dagfactory/dagfactory.py", line 39, in __init__
    self.config: Dict[str, Any] = DagFactory._load_config(
  File "/home/airflow/.local/lib/python3.8/site-packages/dagfactory/dagfactory.py", line 76, in _load_config
    raise DagFactoryConfigException("Invalid DAG Factory config file") from err
dagfactory.exceptions.DagFactoryConfigException: Invalid DAG Factory config file
[2024-03-29T16:56:41.582+0000] {processor.py:842} WARNING - No viable dags retrieved from /opt/airflow/dags/emr_add_step_dag.py
[2024-03-29T16:56:41.619+0000] {processor.py:183} INFO - Processing /opt/airflow/dags/emr_add_step_dag.py took 0.304 seconds
[2024-03-29T16:57:11.808+0000] {processor.py:161} INFO - Started process (PID=56) to work on /opt/airflow/dags/emr_add_step_dag.py
[2024-03-29T16:57:11.808+0000] {processor.py:830} INFO - Processing file /opt/airflow/dags/emr_add_step_dag.py for tasks to queue
[2024-03-29T16:57:11.814+0000] {logging_mixin.py:188} INFO - [2024-03-29T16:57:11.814+0000] {dagbag.py:540} INFO - Filling up the DagBag from /opt/airflow/dags/emr_add_step_dag.py
[2024-03-29T16:57:13.655+0000] {logging_mixin.py:188} INFO - [2024-03-29T16:57:13.650+0000] {dagbag.py:350} ERROR - Failed to import: /opt/airflow/dags/emr_add_step_dag.py
Traceback (most recent call last):
  File "/home/airflow/.local/lib/python3.8/site-packages/dagfactory/dagfactory.py", line 72, in _load_config
    stream=open(config_filepath, "r", encoding="utf-8"),
FileNotFoundError: [Errno 2] No such file or directory: '/opt/airflow/yaml-config/dag_definition_ex1.yaml'

The above exception was the direct cause of the following exception:

Traceback (most recent call last):
  File "/home/airflow/.local/lib/python3.8/site-packages/airflow/models/dagbag.py", line 346, in parse
    loader.exec_module(new_module)
  File "<frozen importlib._bootstrap_external>", line 843, in exec_module
  File "<frozen importlib._bootstrap>", line 219, in _call_with_frames_removed
  File "/opt/airflow/dags/emr_add_step_dag.py", line 45, in <module>
    dag_factory = dagfactory.DagFactory(
  File "/home/airflow/.local/lib/python3.8/site-packages/dagfactory/dagfactory.py", line 39, in __init__
    self.config: Dict[str, Any] = DagFactory._load_config(
  File "/home/airflow/.local/lib/python3.8/site-packages/dagfactory/dagfactory.py", line 76, in _load_config
    raise DagFactoryConfigException("Invalid DAG Factory config file") from err
dagfactory.exceptions.DagFactoryConfigException: Invalid DAG Factory config file
[2024-03-29T16:57:13.656+0000] {processor.py:842} WARNING - No viable dags retrieved from /opt/airflow/dags/emr_add_step_dag.py
[2024-03-29T16:57:13.718+0000] {processor.py:183} INFO - Processing /opt/airflow/dags/emr_add_step_dag.py took 1.914 seconds
[2024-03-29T16:57:44.176+0000] {processor.py:161} INFO - Started process (PID=64) to work on /opt/airflow/dags/emr_add_step_dag.py
[2024-03-29T16:57:44.177+0000] {processor.py:830} INFO - Processing file /opt/airflow/dags/emr_add_step_dag.py for tasks to queue
[2024-03-29T16:57:44.178+0000] {logging_mixin.py:188} INFO - [2024-03-29T16:57:44.178+0000] {dagbag.py:540} INFO - Filling up the DagBag from /opt/airflow/dags/emr_add_step_dag.py
[2024-03-29T16:57:44.468+0000] {logging_mixin.py:188} INFO - [2024-03-29T16:57:44.466+0000] {dagbag.py:350} ERROR - Failed to import: /opt/airflow/dags/emr_add_step_dag.py
Traceback (most recent call last):
  File "/home/airflow/.local/lib/python3.8/site-packages/dagfactory/dagfactory.py", line 72, in _load_config
    stream=open(config_filepath, "r", encoding="utf-8"),
FileNotFoundError: [Errno 2] No such file or directory: '/opt/airflow/yaml-config/dag_definition_ex1.yaml'

The above exception was the direct cause of the following exception:

Traceback (most recent call last):
  File "/home/airflow/.local/lib/python3.8/site-packages/airflow/models/dagbag.py", line 346, in parse
    loader.exec_module(new_module)
  File "<frozen importlib._bootstrap_external>", line 843, in exec_module
  File "<frozen importlib._bootstrap>", line 219, in _call_with_frames_removed
  File "/opt/airflow/dags/emr_add_step_dag.py", line 45, in <module>
    dag_factory = dagfactory.DagFactory(
  File "/home/airflow/.local/lib/python3.8/site-packages/dagfactory/dagfactory.py", line 39, in __init__
    self.config: Dict[str, Any] = DagFactory._load_config(
  File "/home/airflow/.local/lib/python3.8/site-packages/dagfactory/dagfactory.py", line 76, in _load_config
    raise DagFactoryConfigException("Invalid DAG Factory config file") from err
dagfactory.exceptions.DagFactoryConfigException: Invalid DAG Factory config file
[2024-03-29T16:57:44.468+0000] {processor.py:842} WARNING - No viable dags retrieved from /opt/airflow/dags/emr_add_step_dag.py
[2024-03-29T16:57:44.480+0000] {processor.py:183} INFO - Processing /opt/airflow/dags/emr_add_step_dag.py took 0.307 seconds
[2024-03-29T16:58:14.729+0000] {processor.py:161} INFO - Started process (PID=72) to work on /opt/airflow/dags/emr_add_step_dag.py
[2024-03-29T16:58:14.730+0000] {processor.py:830} INFO - Processing file /opt/airflow/dags/emr_add_step_dag.py for tasks to queue
[2024-03-29T16:58:14.732+0000] {logging_mixin.py:188} INFO - [2024-03-29T16:58:14.731+0000] {dagbag.py:540} INFO - Filling up the DagBag from /opt/airflow/dags/emr_add_step_dag.py
[2024-03-29T16:58:14.965+0000] {logging_mixin.py:188} INFO - [2024-03-29T16:58:14.962+0000] {dagbag.py:350} ERROR - Failed to import: /opt/airflow/dags/emr_add_step_dag.py
Traceback (most recent call last):
  File "/home/airflow/.local/lib/python3.8/site-packages/dagfactory/dagfactory.py", line 72, in _load_config
    stream=open(config_filepath, "r", encoding="utf-8"),
FileNotFoundError: [Errno 2] No such file or directory: '/opt/airflow/yaml-config/dag_definition_ex1.yaml'

The above exception was the direct cause of the following exception:

Traceback (most recent call last):
  File "/home/airflow/.local/lib/python3.8/site-packages/airflow/models/dagbag.py", line 346, in parse
    loader.exec_module(new_module)
  File "<frozen importlib._bootstrap_external>", line 843, in exec_module
  File "<frozen importlib._bootstrap>", line 219, in _call_with_frames_removed
  File "/opt/airflow/dags/emr_add_step_dag.py", line 45, in <module>
    dag_factory = dagfactory.DagFactory(
  File "/home/airflow/.local/lib/python3.8/site-packages/dagfactory/dagfactory.py", line 39, in __init__
    self.config: Dict[str, Any] = DagFactory._load_config(
  File "/home/airflow/.local/lib/python3.8/site-packages/dagfactory/dagfactory.py", line 76, in _load_config
    raise DagFactoryConfigException("Invalid DAG Factory config file") from err
dagfactory.exceptions.DagFactoryConfigException: Invalid DAG Factory config file
[2024-03-29T16:58:14.965+0000] {processor.py:842} WARNING - No viable dags retrieved from /opt/airflow/dags/emr_add_step_dag.py
[2024-03-29T16:58:14.985+0000] {processor.py:183} INFO - Processing /opt/airflow/dags/emr_add_step_dag.py took 0.259 seconds
[2024-03-29T16:58:45.033+0000] {processor.py:161} INFO - Started process (PID=80) to work on /opt/airflow/dags/emr_add_step_dag.py
[2024-03-29T16:58:45.034+0000] {processor.py:830} INFO - Processing file /opt/airflow/dags/emr_add_step_dag.py for tasks to queue
[2024-03-29T16:58:45.036+0000] {logging_mixin.py:188} INFO - [2024-03-29T16:58:45.036+0000] {dagbag.py:540} INFO - Filling up the DagBag from /opt/airflow/dags/emr_add_step_dag.py
[2024-03-29T16:58:45.157+0000] {logging_mixin.py:188} INFO - [2024-03-29T16:58:45.154+0000] {dagbag.py:350} ERROR - Failed to import: /opt/airflow/dags/emr_add_step_dag.py
Traceback (most recent call last):
  File "/home/airflow/.local/lib/python3.8/site-packages/dagfactory/dagfactory.py", line 72, in _load_config
    stream=open(config_filepath, "r", encoding="utf-8"),
FileNotFoundError: [Errno 2] No such file or directory: '/opt/airflow/yaml-config/dag_definition_ex1.yaml'

The above exception was the direct cause of the following exception:

Traceback (most recent call last):
  File "/home/airflow/.local/lib/python3.8/site-packages/airflow/models/dagbag.py", line 346, in parse
    loader.exec_module(new_module)
  File "<frozen importlib._bootstrap_external>", line 843, in exec_module
  File "<frozen importlib._bootstrap>", line 219, in _call_with_frames_removed
  File "/opt/airflow/dags/emr_add_step_dag.py", line 45, in <module>
    dag_factory = dagfactory.DagFactory(
  File "/home/airflow/.local/lib/python3.8/site-packages/dagfactory/dagfactory.py", line 39, in __init__
    self.config: Dict[str, Any] = DagFactory._load_config(
  File "/home/airflow/.local/lib/python3.8/site-packages/dagfactory/dagfactory.py", line 76, in _load_config
    raise DagFactoryConfigException("Invalid DAG Factory config file") from err
dagfactory.exceptions.DagFactoryConfigException: Invalid DAG Factory config file
[2024-03-29T16:58:45.157+0000] {processor.py:842} WARNING - No viable dags retrieved from /opt/airflow/dags/emr_add_step_dag.py
[2024-03-29T16:58:45.172+0000] {processor.py:183} INFO - Processing /opt/airflow/dags/emr_add_step_dag.py took 0.142 seconds
[2024-03-29T16:59:15.359+0000] {processor.py:161} INFO - Started process (PID=88) to work on /opt/airflow/dags/emr_add_step_dag.py
[2024-03-29T16:59:15.360+0000] {processor.py:830} INFO - Processing file /opt/airflow/dags/emr_add_step_dag.py for tasks to queue
[2024-03-29T16:59:15.362+0000] {logging_mixin.py:188} INFO - [2024-03-29T16:59:15.362+0000] {dagbag.py:540} INFO - Filling up the DagBag from /opt/airflow/dags/emr_add_step_dag.py
[2024-03-29T16:59:15.610+0000] {logging_mixin.py:188} INFO - [2024-03-29T16:59:15.608+0000] {dagbag.py:350} ERROR - Failed to import: /opt/airflow/dags/emr_add_step_dag.py
Traceback (most recent call last):
  File "/home/airflow/.local/lib/python3.8/site-packages/dagfactory/dagfactory.py", line 72, in _load_config
    stream=open(config_filepath, "r", encoding="utf-8"),
FileNotFoundError: [Errno 2] No such file or directory: '/opt/airflow/yaml-config/dag_definition_ex1.yaml'

The above exception was the direct cause of the following exception:

Traceback (most recent call last):
  File "/home/airflow/.local/lib/python3.8/site-packages/airflow/models/dagbag.py", line 346, in parse
    loader.exec_module(new_module)
  File "<frozen importlib._bootstrap_external>", line 843, in exec_module
  File "<frozen importlib._bootstrap>", line 219, in _call_with_frames_removed
  File "/opt/airflow/dags/emr_add_step_dag.py", line 45, in <module>
    dag_factory = dagfactory.DagFactory(
  File "/home/airflow/.local/lib/python3.8/site-packages/dagfactory/dagfactory.py", line 39, in __init__
    self.config: Dict[str, Any] = DagFactory._load_config(
  File "/home/airflow/.local/lib/python3.8/site-packages/dagfactory/dagfactory.py", line 76, in _load_config
    raise DagFactoryConfigException("Invalid DAG Factory config file") from err
dagfactory.exceptions.DagFactoryConfigException: Invalid DAG Factory config file
[2024-03-29T16:59:15.611+0000] {processor.py:842} WARNING - No viable dags retrieved from /opt/airflow/dags/emr_add_step_dag.py
[2024-03-29T16:59:15.633+0000] {processor.py:183} INFO - Processing /opt/airflow/dags/emr_add_step_dag.py took 0.277 seconds
[2024-03-29T17:01:46.565+0000] {processor.py:161} INFO - Started process (PID=39) to work on /opt/airflow/dags/emr_add_step_dag.py
[2024-03-29T17:01:46.566+0000] {processor.py:830} INFO - Processing file /opt/airflow/dags/emr_add_step_dag.py for tasks to queue
[2024-03-29T17:01:46.568+0000] {logging_mixin.py:188} INFO - [2024-03-29T17:01:46.568+0000] {dagbag.py:540} INFO - Filling up the DagBag from /opt/airflow/dags/emr_add_step_dag.py
[2024-03-29T17:01:47.543+0000] {logging_mixin.py:188} INFO - [2024-03-29T17:01:47.540+0000] {dagbag.py:350} ERROR - Failed to import: /opt/airflow/dags/emr_add_step_dag.py
Traceback (most recent call last):
  File "/home/airflow/.local/lib/python3.8/site-packages/dagfactory/dagfactory.py", line 72, in _load_config
    stream=open(config_filepath, "r", encoding="utf-8"),
FileNotFoundError: [Errno 2] No such file or directory: '/opt/airflow/yaml-config/dag_definition_ex1.yaml'

The above exception was the direct cause of the following exception:

Traceback (most recent call last):
  File "/home/airflow/.local/lib/python3.8/site-packages/airflow/models/dagbag.py", line 346, in parse
    loader.exec_module(new_module)
  File "<frozen importlib._bootstrap_external>", line 843, in exec_module
  File "<frozen importlib._bootstrap>", line 219, in _call_with_frames_removed
  File "/opt/airflow/dags/emr_add_step_dag.py", line 45, in <module>
    dag_factory = dagfactory.DagFactory(
  File "/home/airflow/.local/lib/python3.8/site-packages/dagfactory/dagfactory.py", line 39, in __init__
    self.config: Dict[str, Any] = DagFactory._load_config(
  File "/home/airflow/.local/lib/python3.8/site-packages/dagfactory/dagfactory.py", line 76, in _load_config
    raise DagFactoryConfigException("Invalid DAG Factory config file") from err
dagfactory.exceptions.DagFactoryConfigException: Invalid DAG Factory config file
[2024-03-29T17:01:47.543+0000] {processor.py:842} WARNING - No viable dags retrieved from /opt/airflow/dags/emr_add_step_dag.py
[2024-03-29T17:01:47.566+0000] {processor.py:183} INFO - Processing /opt/airflow/dags/emr_add_step_dag.py took 1.004 seconds
[2024-03-29T17:02:18.352+0000] {processor.py:161} INFO - Started process (PID=48) to work on /opt/airflow/dags/emr_add_step_dag.py
[2024-03-29T17:02:18.353+0000] {processor.py:830} INFO - Processing file /opt/airflow/dags/emr_add_step_dag.py for tasks to queue
[2024-03-29T17:02:18.354+0000] {logging_mixin.py:188} INFO - [2024-03-29T17:02:18.354+0000] {dagbag.py:540} INFO - Filling up the DagBag from /opt/airflow/dags/emr_add_step_dag.py
[2024-03-29T17:02:18.584+0000] {logging_mixin.py:188} INFO - [2024-03-29T17:02:18.581+0000] {dagbag.py:350} ERROR - Failed to import: /opt/airflow/dags/emr_add_step_dag.py
Traceback (most recent call last):
  File "/home/airflow/.local/lib/python3.8/site-packages/dagfactory/dagfactory.py", line 72, in _load_config
    stream=open(config_filepath, "r", encoding="utf-8"),
FileNotFoundError: [Errno 2] No such file or directory: '/opt/airflow/yaml-config/dag_definition_ex1.yaml'

The above exception was the direct cause of the following exception:

Traceback (most recent call last):
  File "/home/airflow/.local/lib/python3.8/site-packages/airflow/models/dagbag.py", line 346, in parse
    loader.exec_module(new_module)
  File "<frozen importlib._bootstrap_external>", line 843, in exec_module
  File "<frozen importlib._bootstrap>", line 219, in _call_with_frames_removed
  File "/opt/airflow/dags/emr_add_step_dag.py", line 45, in <module>
    dag_factory = dagfactory.DagFactory(
  File "/home/airflow/.local/lib/python3.8/site-packages/dagfactory/dagfactory.py", line 39, in __init__
    self.config: Dict[str, Any] = DagFactory._load_config(
  File "/home/airflow/.local/lib/python3.8/site-packages/dagfactory/dagfactory.py", line 76, in _load_config
    raise DagFactoryConfigException("Invalid DAG Factory config file") from err
dagfactory.exceptions.DagFactoryConfigException: Invalid DAG Factory config file
[2024-03-29T17:02:18.585+0000] {processor.py:842} WARNING - No viable dags retrieved from /opt/airflow/dags/emr_add_step_dag.py
[2024-03-29T17:02:18.605+0000] {processor.py:183} INFO - Processing /opt/airflow/dags/emr_add_step_dag.py took 0.256 seconds
[2024-03-29T17:02:48.784+0000] {processor.py:161} INFO - Started process (PID=56) to work on /opt/airflow/dags/emr_add_step_dag.py
[2024-03-29T17:02:48.785+0000] {processor.py:830} INFO - Processing file /opt/airflow/dags/emr_add_step_dag.py for tasks to queue
[2024-03-29T17:02:48.788+0000] {logging_mixin.py:188} INFO - [2024-03-29T17:02:48.786+0000] {dagbag.py:540} INFO - Filling up the DagBag from /opt/airflow/dags/emr_add_step_dag.py
[2024-03-29T17:02:49.996+0000] {logging_mixin.py:188} INFO - [2024-03-29T17:02:49.993+0000] {dagbag.py:350} ERROR - Failed to import: /opt/airflow/dags/emr_add_step_dag.py
Traceback (most recent call last):
  File "/home/airflow/.local/lib/python3.8/site-packages/dagfactory/dagfactory.py", line 72, in _load_config
    stream=open(config_filepath, "r", encoding="utf-8"),
FileNotFoundError: [Errno 2] No such file or directory: '/opt/airflow/yaml-config/dag_definition_ex1.yaml'

The above exception was the direct cause of the following exception:

Traceback (most recent call last):
  File "/home/airflow/.local/lib/python3.8/site-packages/airflow/models/dagbag.py", line 346, in parse
    loader.exec_module(new_module)
  File "<frozen importlib._bootstrap_external>", line 843, in exec_module
  File "<frozen importlib._bootstrap>", line 219, in _call_with_frames_removed
  File "/opt/airflow/dags/emr_add_step_dag.py", line 45, in <module>
    dag_factory = dagfactory.DagFactory(
  File "/home/airflow/.local/lib/python3.8/site-packages/dagfactory/dagfactory.py", line 39, in __init__
    self.config: Dict[str, Any] = DagFactory._load_config(
  File "/home/airflow/.local/lib/python3.8/site-packages/dagfactory/dagfactory.py", line 76, in _load_config
    raise DagFactoryConfigException("Invalid DAG Factory config file") from err
dagfactory.exceptions.DagFactoryConfigException: Invalid DAG Factory config file
[2024-03-29T17:02:49.996+0000] {processor.py:842} WARNING - No viable dags retrieved from /opt/airflow/dags/emr_add_step_dag.py
[2024-03-29T17:02:50.013+0000] {processor.py:183} INFO - Processing /opt/airflow/dags/emr_add_step_dag.py took 1.234 seconds
[2024-03-29T17:03:20.170+0000] {processor.py:161} INFO - Started process (PID=64) to work on /opt/airflow/dags/emr_add_step_dag.py
[2024-03-29T17:03:20.171+0000] {processor.py:830} INFO - Processing file /opt/airflow/dags/emr_add_step_dag.py for tasks to queue
[2024-03-29T17:03:20.173+0000] {logging_mixin.py:188} INFO - [2024-03-29T17:03:20.173+0000] {dagbag.py:540} INFO - Filling up the DagBag from /opt/airflow/dags/emr_add_step_dag.py
[2024-03-29T17:03:20.494+0000] {logging_mixin.py:188} INFO - [2024-03-29T17:03:20.491+0000] {dagbag.py:350} ERROR - Failed to import: /opt/airflow/dags/emr_add_step_dag.py
Traceback (most recent call last):
  File "/home/airflow/.local/lib/python3.8/site-packages/dagfactory/dagfactory.py", line 72, in _load_config
    stream=open(config_filepath, "r", encoding="utf-8"),
FileNotFoundError: [Errno 2] No such file or directory: '/opt/airflow/yaml-config/dag_definition_ex1.yaml'

The above exception was the direct cause of the following exception:

Traceback (most recent call last):
  File "/home/airflow/.local/lib/python3.8/site-packages/airflow/models/dagbag.py", line 346, in parse
    loader.exec_module(new_module)
  File "<frozen importlib._bootstrap_external>", line 843, in exec_module
  File "<frozen importlib._bootstrap>", line 219, in _call_with_frames_removed
  File "/opt/airflow/dags/emr_add_step_dag.py", line 45, in <module>
    dag_factory = dagfactory.DagFactory(
  File "/home/airflow/.local/lib/python3.8/site-packages/dagfactory/dagfactory.py", line 39, in __init__
    self.config: Dict[str, Any] = DagFactory._load_config(
  File "/home/airflow/.local/lib/python3.8/site-packages/dagfactory/dagfactory.py", line 76, in _load_config
    raise DagFactoryConfigException("Invalid DAG Factory config file") from err
dagfactory.exceptions.DagFactoryConfigException: Invalid DAG Factory config file
[2024-03-29T17:03:20.495+0000] {processor.py:842} WARNING - No viable dags retrieved from /opt/airflow/dags/emr_add_step_dag.py
[2024-03-29T17:03:20.507+0000] {processor.py:183} INFO - Processing /opt/airflow/dags/emr_add_step_dag.py took 0.340 seconds
[2024-03-29T17:04:41.856+0000] {processor.py:161} INFO - Started process (PID=39) to work on /opt/airflow/dags/emr_add_step_dag.py
[2024-03-29T17:04:41.857+0000] {processor.py:830} INFO - Processing file /opt/airflow/dags/emr_add_step_dag.py for tasks to queue
[2024-03-29T17:04:41.859+0000] {logging_mixin.py:188} INFO - [2024-03-29T17:04:41.859+0000] {dagbag.py:540} INFO - Filling up the DagBag from /opt/airflow/dags/emr_add_step_dag.py
[2024-03-29T17:04:42.890+0000] {logging_mixin.py:188} INFO - [2024-03-29T17:04:42.887+0000] {dagbag.py:350} ERROR - Failed to import: /opt/airflow/dags/emr_add_step_dag.py
Traceback (most recent call last):
  File "/home/airflow/.local/lib/python3.8/site-packages/dagfactory/dagfactory.py", line 72, in _load_config
    stream=open(config_filepath, "r", encoding="utf-8"),
FileNotFoundError: [Errno 2] No such file or directory: '/opt/airflow/yaml-config/dag_definition_ex1.yaml'

The above exception was the direct cause of the following exception:

Traceback (most recent call last):
  File "/home/airflow/.local/lib/python3.8/site-packages/airflow/models/dagbag.py", line 346, in parse
    loader.exec_module(new_module)
  File "<frozen importlib._bootstrap_external>", line 843, in exec_module
  File "<frozen importlib._bootstrap>", line 219, in _call_with_frames_removed
  File "/opt/airflow/dags/emr_add_step_dag.py", line 45, in <module>
    dag_factory = dagfactory.DagFactory(
  File "/home/airflow/.local/lib/python3.8/site-packages/dagfactory/dagfactory.py", line 39, in __init__
    self.config: Dict[str, Any] = DagFactory._load_config(
  File "/home/airflow/.local/lib/python3.8/site-packages/dagfactory/dagfactory.py", line 76, in _load_config
    raise DagFactoryConfigException("Invalid DAG Factory config file") from err
dagfactory.exceptions.DagFactoryConfigException: Invalid DAG Factory config file
[2024-03-29T17:04:42.890+0000] {processor.py:842} WARNING - No viable dags retrieved from /opt/airflow/dags/emr_add_step_dag.py
[2024-03-29T17:04:42.904+0000] {processor.py:183} INFO - Processing /opt/airflow/dags/emr_add_step_dag.py took 1.051 seconds
[2024-03-29T17:05:13.619+0000] {processor.py:161} INFO - Started process (PID=48) to work on /opt/airflow/dags/emr_add_step_dag.py
[2024-03-29T17:05:13.620+0000] {processor.py:830} INFO - Processing file /opt/airflow/dags/emr_add_step_dag.py for tasks to queue
[2024-03-29T17:05:13.621+0000] {logging_mixin.py:188} INFO - [2024-03-29T17:05:13.621+0000] {dagbag.py:540} INFO - Filling up the DagBag from /opt/airflow/dags/emr_add_step_dag.py
[2024-03-29T17:05:13.853+0000] {logging_mixin.py:188} INFO - [2024-03-29T17:05:13.850+0000] {dagbag.py:350} ERROR - Failed to import: /opt/airflow/dags/emr_add_step_dag.py
Traceback (most recent call last):
  File "/home/airflow/.local/lib/python3.8/site-packages/dagfactory/dagfactory.py", line 72, in _load_config
    stream=open(config_filepath, "r", encoding="utf-8"),
FileNotFoundError: [Errno 2] No such file or directory: '/opt/airflow/yaml-config/dag_definition_ex1.yaml'

The above exception was the direct cause of the following exception:

Traceback (most recent call last):
  File "/home/airflow/.local/lib/python3.8/site-packages/airflow/models/dagbag.py", line 346, in parse
    loader.exec_module(new_module)
  File "<frozen importlib._bootstrap_external>", line 843, in exec_module
  File "<frozen importlib._bootstrap>", line 219, in _call_with_frames_removed
  File "/opt/airflow/dags/emr_add_step_dag.py", line 45, in <module>
    dag_factory = dagfactory.DagFactory(
  File "/home/airflow/.local/lib/python3.8/site-packages/dagfactory/dagfactory.py", line 39, in __init__
    self.config: Dict[str, Any] = DagFactory._load_config(
  File "/home/airflow/.local/lib/python3.8/site-packages/dagfactory/dagfactory.py", line 76, in _load_config
    raise DagFactoryConfigException("Invalid DAG Factory config file") from err
dagfactory.exceptions.DagFactoryConfigException: Invalid DAG Factory config file
[2024-03-29T17:05:13.853+0000] {processor.py:842} WARNING - No viable dags retrieved from /opt/airflow/dags/emr_add_step_dag.py
[2024-03-29T17:05:13.875+0000] {processor.py:183} INFO - Processing /opt/airflow/dags/emr_add_step_dag.py took 0.258 seconds
[2024-03-29T17:05:44.057+0000] {processor.py:161} INFO - Started process (PID=56) to work on /opt/airflow/dags/emr_add_step_dag.py
[2024-03-29T17:05:44.058+0000] {processor.py:830} INFO - Processing file /opt/airflow/dags/emr_add_step_dag.py for tasks to queue
[2024-03-29T17:05:44.061+0000] {logging_mixin.py:188} INFO - [2024-03-29T17:05:44.061+0000] {dagbag.py:540} INFO - Filling up the DagBag from /opt/airflow/dags/emr_add_step_dag.py
[2024-03-29T17:05:46.063+0000] {logging_mixin.py:188} INFO - [2024-03-29T17:05:46.061+0000] {dagbag.py:350} ERROR - Failed to import: /opt/airflow/dags/emr_add_step_dag.py
Traceback (most recent call last):
  File "/home/airflow/.local/lib/python3.8/site-packages/dagfactory/dagfactory.py", line 72, in _load_config
    stream=open(config_filepath, "r", encoding="utf-8"),
FileNotFoundError: [Errno 2] No such file or directory: '/opt/airflow/yaml-config/dag_definition_ex1.yaml'

The above exception was the direct cause of the following exception:

Traceback (most recent call last):
  File "/home/airflow/.local/lib/python3.8/site-packages/airflow/models/dagbag.py", line 346, in parse
    loader.exec_module(new_module)
  File "<frozen importlib._bootstrap_external>", line 843, in exec_module
  File "<frozen importlib._bootstrap>", line 219, in _call_with_frames_removed
  File "/opt/airflow/dags/emr_add_step_dag.py", line 45, in <module>
    dag_factory = dagfactory.DagFactory(
  File "/home/airflow/.local/lib/python3.8/site-packages/dagfactory/dagfactory.py", line 39, in __init__
    self.config: Dict[str, Any] = DagFactory._load_config(
  File "/home/airflow/.local/lib/python3.8/site-packages/dagfactory/dagfactory.py", line 76, in _load_config
    raise DagFactoryConfigException("Invalid DAG Factory config file") from err
dagfactory.exceptions.DagFactoryConfigException: Invalid DAG Factory config file
[2024-03-29T17:05:46.064+0000] {processor.py:842} WARNING - No viable dags retrieved from /opt/airflow/dags/emr_add_step_dag.py
[2024-03-29T17:05:46.152+0000] {processor.py:183} INFO - Processing /opt/airflow/dags/emr_add_step_dag.py took 2.099 seconds
[2024-03-29T17:06:49.311+0000] {processor.py:161} INFO - Started process (PID=39) to work on /opt/airflow/dags/emr_add_step_dag.py
[2024-03-29T17:06:49.312+0000] {processor.py:830} INFO - Processing file /opt/airflow/dags/emr_add_step_dag.py for tasks to queue
[2024-03-29T17:06:49.314+0000] {logging_mixin.py:188} INFO - [2024-03-29T17:06:49.314+0000] {dagbag.py:540} INFO - Filling up the DagBag from /opt/airflow/dags/emr_add_step_dag.py
[2024-03-29T17:06:50.264+0000] {logging_mixin.py:188} INFO - [2024-03-29T17:06:50.262+0000] {dagbag.py:350} ERROR - Failed to import: /opt/airflow/dags/emr_add_step_dag.py
Traceback (most recent call last):
  File "/home/airflow/.local/lib/python3.8/site-packages/dagfactory/dagfactory.py", line 72, in _load_config
    stream=open(config_filepath, "r", encoding="utf-8"),
FileNotFoundError: [Errno 2] No such file or directory: '/opt/airflow/yaml-config/dag_definition_ex1.yaml'

The above exception was the direct cause of the following exception:

Traceback (most recent call last):
  File "/home/airflow/.local/lib/python3.8/site-packages/airflow/models/dagbag.py", line 346, in parse
    loader.exec_module(new_module)
  File "<frozen importlib._bootstrap_external>", line 843, in exec_module
  File "<frozen importlib._bootstrap>", line 219, in _call_with_frames_removed
  File "/opt/airflow/dags/emr_add_step_dag.py", line 45, in <module>
    dag_factory = dagfactory.DagFactory(
  File "/home/airflow/.local/lib/python3.8/site-packages/dagfactory/dagfactory.py", line 39, in __init__
    self.config: Dict[str, Any] = DagFactory._load_config(
  File "/home/airflow/.local/lib/python3.8/site-packages/dagfactory/dagfactory.py", line 76, in _load_config
    raise DagFactoryConfigException("Invalid DAG Factory config file") from err
dagfactory.exceptions.DagFactoryConfigException: Invalid DAG Factory config file
[2024-03-29T17:06:50.265+0000] {processor.py:842} WARNING - No viable dags retrieved from /opt/airflow/dags/emr_add_step_dag.py
[2024-03-29T17:06:50.289+0000] {processor.py:183} INFO - Processing /opt/airflow/dags/emr_add_step_dag.py took 0.980 seconds
[2024-03-29T17:07:21.144+0000] {processor.py:161} INFO - Started process (PID=48) to work on /opt/airflow/dags/emr_add_step_dag.py
[2024-03-29T17:07:21.144+0000] {processor.py:830} INFO - Processing file /opt/airflow/dags/emr_add_step_dag.py for tasks to queue
[2024-03-29T17:07:21.146+0000] {logging_mixin.py:188} INFO - [2024-03-29T17:07:21.146+0000] {dagbag.py:540} INFO - Filling up the DagBag from /opt/airflow/dags/emr_add_step_dag.py
[2024-03-29T17:07:21.396+0000] {logging_mixin.py:188} INFO - [2024-03-29T17:07:21.394+0000] {dagbag.py:350} ERROR - Failed to import: /opt/airflow/dags/emr_add_step_dag.py
Traceback (most recent call last):
  File "/home/airflow/.local/lib/python3.8/site-packages/dagfactory/dagfactory.py", line 72, in _load_config
    stream=open(config_filepath, "r", encoding="utf-8"),
FileNotFoundError: [Errno 2] No such file or directory: '/opt/airflow/yaml-config/dag_definition_ex1.yaml'

The above exception was the direct cause of the following exception:

Traceback (most recent call last):
  File "/home/airflow/.local/lib/python3.8/site-packages/airflow/models/dagbag.py", line 346, in parse
    loader.exec_module(new_module)
  File "<frozen importlib._bootstrap_external>", line 843, in exec_module
  File "<frozen importlib._bootstrap>", line 219, in _call_with_frames_removed
  File "/opt/airflow/dags/emr_add_step_dag.py", line 45, in <module>
    dag_factory = dagfactory.DagFactory(
  File "/home/airflow/.local/lib/python3.8/site-packages/dagfactory/dagfactory.py", line 39, in __init__
    self.config: Dict[str, Any] = DagFactory._load_config(
  File "/home/airflow/.local/lib/python3.8/site-packages/dagfactory/dagfactory.py", line 76, in _load_config
    raise DagFactoryConfigException("Invalid DAG Factory config file") from err
dagfactory.exceptions.DagFactoryConfigException: Invalid DAG Factory config file
[2024-03-29T17:07:21.397+0000] {processor.py:842} WARNING - No viable dags retrieved from /opt/airflow/dags/emr_add_step_dag.py
[2024-03-29T17:07:21.418+0000] {processor.py:183} INFO - Processing /opt/airflow/dags/emr_add_step_dag.py took 0.277 seconds
[2024-03-29T17:07:51.513+0000] {processor.py:161} INFO - Started process (PID=56) to work on /opt/airflow/dags/emr_add_step_dag.py
[2024-03-29T17:07:51.514+0000] {processor.py:830} INFO - Processing file /opt/airflow/dags/emr_add_step_dag.py for tasks to queue
[2024-03-29T17:07:51.516+0000] {logging_mixin.py:188} INFO - [2024-03-29T17:07:51.516+0000] {dagbag.py:540} INFO - Filling up the DagBag from /opt/airflow/dags/emr_add_step_dag.py
[2024-03-29T17:07:51.764+0000] {logging_mixin.py:188} INFO - [2024-03-29T17:07:51.761+0000] {dagbag.py:350} ERROR - Failed to import: /opt/airflow/dags/emr_add_step_dag.py
Traceback (most recent call last):
  File "/home/airflow/.local/lib/python3.8/site-packages/dagfactory/dagfactory.py", line 72, in _load_config
    stream=open(config_filepath, "r", encoding="utf-8"),
FileNotFoundError: [Errno 2] No such file or directory: '/opt/airflow/yaml-config/dag_definition_ex1.yaml'

The above exception was the direct cause of the following exception:

Traceback (most recent call last):
  File "/home/airflow/.local/lib/python3.8/site-packages/airflow/models/dagbag.py", line 346, in parse
    loader.exec_module(new_module)
  File "<frozen importlib._bootstrap_external>", line 843, in exec_module
  File "<frozen importlib._bootstrap>", line 219, in _call_with_frames_removed
  File "/opt/airflow/dags/emr_add_step_dag.py", line 45, in <module>
    dag_factory = dagfactory.DagFactory(
  File "/home/airflow/.local/lib/python3.8/site-packages/dagfactory/dagfactory.py", line 39, in __init__
    self.config: Dict[str, Any] = DagFactory._load_config(
  File "/home/airflow/.local/lib/python3.8/site-packages/dagfactory/dagfactory.py", line 76, in _load_config
    raise DagFactoryConfigException("Invalid DAG Factory config file") from err
dagfactory.exceptions.DagFactoryConfigException: Invalid DAG Factory config file
[2024-03-29T17:07:51.764+0000] {processor.py:842} WARNING - No viable dags retrieved from /opt/airflow/dags/emr_add_step_dag.py
[2024-03-29T17:07:51.787+0000] {processor.py:183} INFO - Processing /opt/airflow/dags/emr_add_step_dag.py took 0.277 seconds
[2024-03-29T17:08:09.619+0000] {processor.py:161} INFO - Started process (PID=63) to work on /opt/airflow/dags/emr_add_step_dag.py
[2024-03-29T17:08:09.620+0000] {processor.py:830} INFO - Processing file /opt/airflow/dags/emr_add_step_dag.py for tasks to queue
[2024-03-29T17:08:09.621+0000] {logging_mixin.py:188} INFO - [2024-03-29T17:08:09.621+0000] {dagbag.py:540} INFO - Filling up the DagBag from /opt/airflow/dags/emr_add_step_dag.py
[2024-03-29T17:08:09.870+0000] {logging_mixin.py:188} INFO - [2024-03-29T17:08:09.868+0000] {dagbag.py:350} ERROR - Failed to import: /opt/airflow/dags/emr_add_step_dag.py
Traceback (most recent call last):
  File "/home/airflow/.local/lib/python3.8/site-packages/dagfactory/dagfactory.py", line 71, in _load_config
    config: Dict[str, Any] = yaml.load(
  File "/home/airflow/.local/lib/python3.8/site-packages/yaml/__init__.py", line 81, in load
    return loader.get_single_data()
  File "/home/airflow/.local/lib/python3.8/site-packages/yaml/constructor.py", line 51, in get_single_data
    return self.construct_document(node)
  File "/home/airflow/.local/lib/python3.8/site-packages/yaml/constructor.py", line 60, in construct_document
    for dummy in generator:
  File "/home/airflow/.local/lib/python3.8/site-packages/yaml/constructor.py", line 413, in construct_yaml_map
    value = self.construct_mapping(node)
  File "/home/airflow/.local/lib/python3.8/site-packages/yaml/constructor.py", line 218, in construct_mapping
    return super().construct_mapping(node, deep=deep)
  File "/home/airflow/.local/lib/python3.8/site-packages/yaml/constructor.py", line 141, in construct_mapping
    raise ConstructorError("while constructing a mapping", node.start_mark,
yaml.constructor.ConstructorError: while constructing a mapping
  in "/opt/airflow/yaml/dag_definition_ex1.yaml", line 37, column 20
found unhashable key
  in "/opt/airflow/yaml/dag_definition_ex1.yaml", line 37, column 21

The above exception was the direct cause of the following exception:

Traceback (most recent call last):
  File "/home/airflow/.local/lib/python3.8/site-packages/airflow/models/dagbag.py", line 346, in parse
    loader.exec_module(new_module)
  File "<frozen importlib._bootstrap_external>", line 843, in exec_module
  File "<frozen importlib._bootstrap>", line 219, in _call_with_frames_removed
  File "/opt/airflow/dags/emr_add_step_dag.py", line 45, in <module>
    dag_factory = dagfactory.DagFactory(
  File "/home/airflow/.local/lib/python3.8/site-packages/dagfactory/dagfactory.py", line 39, in __init__
    self.config: Dict[str, Any] = DagFactory._load_config(
  File "/home/airflow/.local/lib/python3.8/site-packages/dagfactory/dagfactory.py", line 76, in _load_config
    raise DagFactoryConfigException("Invalid DAG Factory config file") from err
dagfactory.exceptions.DagFactoryConfigException: Invalid DAG Factory config file
[2024-03-29T17:08:09.871+0000] {processor.py:842} WARNING - No viable dags retrieved from /opt/airflow/dags/emr_add_step_dag.py
[2024-03-29T17:08:09.883+0000] {processor.py:183} INFO - Processing /opt/airflow/dags/emr_add_step_dag.py took 0.267 seconds
[2024-03-29T17:08:39.999+0000] {processor.py:161} INFO - Started process (PID=71) to work on /opt/airflow/dags/emr_add_step_dag.py
[2024-03-29T17:08:40.000+0000] {processor.py:830} INFO - Processing file /opt/airflow/dags/emr_add_step_dag.py for tasks to queue
[2024-03-29T17:08:40.002+0000] {logging_mixin.py:188} INFO - [2024-03-29T17:08:40.002+0000] {dagbag.py:540} INFO - Filling up the DagBag from /opt/airflow/dags/emr_add_step_dag.py
[2024-03-29T17:08:40.445+0000] {logging_mixin.py:188} INFO - [2024-03-29T17:08:40.443+0000] {dagbag.py:350} ERROR - Failed to import: /opt/airflow/dags/emr_add_step_dag.py
Traceback (most recent call last):
  File "/home/airflow/.local/lib/python3.8/site-packages/dagfactory/dagfactory.py", line 71, in _load_config
    config: Dict[str, Any] = yaml.load(
  File "/home/airflow/.local/lib/python3.8/site-packages/yaml/__init__.py", line 81, in load
    return loader.get_single_data()
  File "/home/airflow/.local/lib/python3.8/site-packages/yaml/constructor.py", line 51, in get_single_data
    return self.construct_document(node)
  File "/home/airflow/.local/lib/python3.8/site-packages/yaml/constructor.py", line 60, in construct_document
    for dummy in generator:
  File "/home/airflow/.local/lib/python3.8/site-packages/yaml/constructor.py", line 413, in construct_yaml_map
    value = self.construct_mapping(node)
  File "/home/airflow/.local/lib/python3.8/site-packages/yaml/constructor.py", line 218, in construct_mapping
    return super().construct_mapping(node, deep=deep)
  File "/home/airflow/.local/lib/python3.8/site-packages/yaml/constructor.py", line 141, in construct_mapping
    raise ConstructorError("while constructing a mapping", node.start_mark,
yaml.constructor.ConstructorError: while constructing a mapping
  in "/opt/airflow/yaml/dag_definition_ex1.yaml", line 37, column 20
found unhashable key
  in "/opt/airflow/yaml/dag_definition_ex1.yaml", line 37, column 21

The above exception was the direct cause of the following exception:

Traceback (most recent call last):
  File "/home/airflow/.local/lib/python3.8/site-packages/airflow/models/dagbag.py", line 346, in parse
    loader.exec_module(new_module)
  File "<frozen importlib._bootstrap_external>", line 843, in exec_module
  File "<frozen importlib._bootstrap>", line 219, in _call_with_frames_removed
  File "/opt/airflow/dags/emr_add_step_dag.py", line 45, in <module>
    dag_factory = dagfactory.DagFactory(
  File "/home/airflow/.local/lib/python3.8/site-packages/dagfactory/dagfactory.py", line 39, in __init__
    self.config: Dict[str, Any] = DagFactory._load_config(
  File "/home/airflow/.local/lib/python3.8/site-packages/dagfactory/dagfactory.py", line 76, in _load_config
    raise DagFactoryConfigException("Invalid DAG Factory config file") from err
dagfactory.exceptions.DagFactoryConfigException: Invalid DAG Factory config file
[2024-03-29T17:08:40.445+0000] {processor.py:842} WARNING - No viable dags retrieved from /opt/airflow/dags/emr_add_step_dag.py
[2024-03-29T17:08:40.555+0000] {processor.py:183} INFO - Processing /opt/airflow/dags/emr_add_step_dag.py took 0.559 seconds
[2024-03-29T17:09:10.742+0000] {processor.py:161} INFO - Started process (PID=79) to work on /opt/airflow/dags/emr_add_step_dag.py
[2024-03-29T17:09:10.744+0000] {processor.py:830} INFO - Processing file /opt/airflow/dags/emr_add_step_dag.py for tasks to queue
[2024-03-29T17:09:10.746+0000] {logging_mixin.py:188} INFO - [2024-03-29T17:09:10.746+0000] {dagbag.py:540} INFO - Filling up the DagBag from /opt/airflow/dags/emr_add_step_dag.py
[2024-03-29T17:09:11.047+0000] {logging_mixin.py:188} INFO - [2024-03-29T17:09:11.044+0000] {dagbag.py:350} ERROR - Failed to import: /opt/airflow/dags/emr_add_step_dag.py
Traceback (most recent call last):
  File "/home/airflow/.local/lib/python3.8/site-packages/dagfactory/dagfactory.py", line 71, in _load_config
    config: Dict[str, Any] = yaml.load(
  File "/home/airflow/.local/lib/python3.8/site-packages/yaml/__init__.py", line 81, in load
    return loader.get_single_data()
  File "/home/airflow/.local/lib/python3.8/site-packages/yaml/constructor.py", line 51, in get_single_data
    return self.construct_document(node)
  File "/home/airflow/.local/lib/python3.8/site-packages/yaml/constructor.py", line 60, in construct_document
    for dummy in generator:
  File "/home/airflow/.local/lib/python3.8/site-packages/yaml/constructor.py", line 413, in construct_yaml_map
    value = self.construct_mapping(node)
  File "/home/airflow/.local/lib/python3.8/site-packages/yaml/constructor.py", line 218, in construct_mapping
    return super().construct_mapping(node, deep=deep)
  File "/home/airflow/.local/lib/python3.8/site-packages/yaml/constructor.py", line 141, in construct_mapping
    raise ConstructorError("while constructing a mapping", node.start_mark,
yaml.constructor.ConstructorError: while constructing a mapping
  in "/opt/airflow/yaml/dag_definition_ex1.yaml", line 37, column 20
found unhashable key
  in "/opt/airflow/yaml/dag_definition_ex1.yaml", line 37, column 21

The above exception was the direct cause of the following exception:

Traceback (most recent call last):
  File "/home/airflow/.local/lib/python3.8/site-packages/airflow/models/dagbag.py", line 346, in parse
    loader.exec_module(new_module)
  File "<frozen importlib._bootstrap_external>", line 843, in exec_module
  File "<frozen importlib._bootstrap>", line 219, in _call_with_frames_removed
  File "/opt/airflow/dags/emr_add_step_dag.py", line 45, in <module>
    dag_factory = dagfactory.DagFactory(
  File "/home/airflow/.local/lib/python3.8/site-packages/dagfactory/dagfactory.py", line 39, in __init__
    self.config: Dict[str, Any] = DagFactory._load_config(
  File "/home/airflow/.local/lib/python3.8/site-packages/dagfactory/dagfactory.py", line 76, in _load_config
    raise DagFactoryConfigException("Invalid DAG Factory config file") from err
dagfactory.exceptions.DagFactoryConfigException: Invalid DAG Factory config file
[2024-03-29T17:09:11.048+0000] {processor.py:842} WARNING - No viable dags retrieved from /opt/airflow/dags/emr_add_step_dag.py
[2024-03-29T17:09:11.071+0000] {processor.py:183} INFO - Processing /opt/airflow/dags/emr_add_step_dag.py took 0.331 seconds
[2024-03-29T17:09:41.143+0000] {processor.py:161} INFO - Started process (PID=87) to work on /opt/airflow/dags/emr_add_step_dag.py
[2024-03-29T17:09:41.144+0000] {processor.py:830} INFO - Processing file /opt/airflow/dags/emr_add_step_dag.py for tasks to queue
[2024-03-29T17:09:41.146+0000] {logging_mixin.py:188} INFO - [2024-03-29T17:09:41.146+0000] {dagbag.py:540} INFO - Filling up the DagBag from /opt/airflow/dags/emr_add_step_dag.py
[2024-03-29T17:09:41.420+0000] {logging_mixin.py:188} INFO - [2024-03-29T17:09:41.417+0000] {dagbag.py:350} ERROR - Failed to import: /opt/airflow/dags/emr_add_step_dag.py
Traceback (most recent call last):
  File "/home/airflow/.local/lib/python3.8/site-packages/dagfactory/dagfactory.py", line 71, in _load_config
    config: Dict[str, Any] = yaml.load(
  File "/home/airflow/.local/lib/python3.8/site-packages/yaml/__init__.py", line 81, in load
    return loader.get_single_data()
  File "/home/airflow/.local/lib/python3.8/site-packages/yaml/constructor.py", line 51, in get_single_data
    return self.construct_document(node)
  File "/home/airflow/.local/lib/python3.8/site-packages/yaml/constructor.py", line 60, in construct_document
    for dummy in generator:
  File "/home/airflow/.local/lib/python3.8/site-packages/yaml/constructor.py", line 413, in construct_yaml_map
    value = self.construct_mapping(node)
  File "/home/airflow/.local/lib/python3.8/site-packages/yaml/constructor.py", line 218, in construct_mapping
    return super().construct_mapping(node, deep=deep)
  File "/home/airflow/.local/lib/python3.8/site-packages/yaml/constructor.py", line 141, in construct_mapping
    raise ConstructorError("while constructing a mapping", node.start_mark,
yaml.constructor.ConstructorError: while constructing a mapping
  in "/opt/airflow/yaml/dag_definition_ex1.yaml", line 37, column 20
found unhashable key
  in "/opt/airflow/yaml/dag_definition_ex1.yaml", line 37, column 21

The above exception was the direct cause of the following exception:

Traceback (most recent call last):
  File "/home/airflow/.local/lib/python3.8/site-packages/airflow/models/dagbag.py", line 346, in parse
    loader.exec_module(new_module)
  File "<frozen importlib._bootstrap_external>", line 843, in exec_module
  File "<frozen importlib._bootstrap>", line 219, in _call_with_frames_removed
  File "/opt/airflow/dags/emr_add_step_dag.py", line 45, in <module>
    dag_factory = dagfactory.DagFactory(
  File "/home/airflow/.local/lib/python3.8/site-packages/dagfactory/dagfactory.py", line 39, in __init__
    self.config: Dict[str, Any] = DagFactory._load_config(
  File "/home/airflow/.local/lib/python3.8/site-packages/dagfactory/dagfactory.py", line 76, in _load_config
    raise DagFactoryConfigException("Invalid DAG Factory config file") from err
dagfactory.exceptions.DagFactoryConfigException: Invalid DAG Factory config file
[2024-03-29T17:09:41.421+0000] {processor.py:842} WARNING - No viable dags retrieved from /opt/airflow/dags/emr_add_step_dag.py
[2024-03-29T17:09:41.436+0000] {processor.py:183} INFO - Processing /opt/airflow/dags/emr_add_step_dag.py took 0.295 seconds
[2024-03-29T17:10:12.357+0000] {processor.py:161} INFO - Started process (PID=96) to work on /opt/airflow/dags/emr_add_step_dag.py
[2024-03-29T17:10:12.358+0000] {processor.py:830} INFO - Processing file /opt/airflow/dags/emr_add_step_dag.py for tasks to queue
[2024-03-29T17:10:12.359+0000] {logging_mixin.py:188} INFO - [2024-03-29T17:10:12.359+0000] {dagbag.py:540} INFO - Filling up the DagBag from /opt/airflow/dags/emr_add_step_dag.py
[2024-03-29T17:10:12.581+0000] {logging_mixin.py:188} INFO - [2024-03-29T17:10:12.578+0000] {dagbag.py:350} ERROR - Failed to import: /opt/airflow/dags/emr_add_step_dag.py
Traceback (most recent call last):
  File "/home/airflow/.local/lib/python3.8/site-packages/dagfactory/dagfactory.py", line 71, in _load_config
    config: Dict[str, Any] = yaml.load(
  File "/home/airflow/.local/lib/python3.8/site-packages/yaml/__init__.py", line 81, in load
    return loader.get_single_data()
  File "/home/airflow/.local/lib/python3.8/site-packages/yaml/constructor.py", line 51, in get_single_data
    return self.construct_document(node)
  File "/home/airflow/.local/lib/python3.8/site-packages/yaml/constructor.py", line 60, in construct_document
    for dummy in generator:
  File "/home/airflow/.local/lib/python3.8/site-packages/yaml/constructor.py", line 413, in construct_yaml_map
    value = self.construct_mapping(node)
  File "/home/airflow/.local/lib/python3.8/site-packages/yaml/constructor.py", line 218, in construct_mapping
    return super().construct_mapping(node, deep=deep)
  File "/home/airflow/.local/lib/python3.8/site-packages/yaml/constructor.py", line 141, in construct_mapping
    raise ConstructorError("while constructing a mapping", node.start_mark,
yaml.constructor.ConstructorError: while constructing a mapping
  in "/opt/airflow/yaml/dag_definition_ex1.yaml", line 37, column 20
found unhashable key
  in "/opt/airflow/yaml/dag_definition_ex1.yaml", line 37, column 21

The above exception was the direct cause of the following exception:

Traceback (most recent call last):
  File "/home/airflow/.local/lib/python3.8/site-packages/airflow/models/dagbag.py", line 346, in parse
    loader.exec_module(new_module)
  File "<frozen importlib._bootstrap_external>", line 843, in exec_module
  File "<frozen importlib._bootstrap>", line 219, in _call_with_frames_removed
  File "/opt/airflow/dags/emr_add_step_dag.py", line 45, in <module>
    dag_factory = dagfactory.DagFactory(
  File "/home/airflow/.local/lib/python3.8/site-packages/dagfactory/dagfactory.py", line 39, in __init__
    self.config: Dict[str, Any] = DagFactory._load_config(
  File "/home/airflow/.local/lib/python3.8/site-packages/dagfactory/dagfactory.py", line 76, in _load_config
    raise DagFactoryConfigException("Invalid DAG Factory config file") from err
dagfactory.exceptions.DagFactoryConfigException: Invalid DAG Factory config file
[2024-03-29T17:10:12.582+0000] {processor.py:842} WARNING - No viable dags retrieved from /opt/airflow/dags/emr_add_step_dag.py
[2024-03-29T17:10:12.603+0000] {processor.py:183} INFO - Processing /opt/airflow/dags/emr_add_step_dag.py took 0.249 seconds
[2024-03-29T17:10:42.660+0000] {processor.py:161} INFO - Started process (PID=104) to work on /opt/airflow/dags/emr_add_step_dag.py
[2024-03-29T17:10:42.660+0000] {processor.py:830} INFO - Processing file /opt/airflow/dags/emr_add_step_dag.py for tasks to queue
[2024-03-29T17:10:42.662+0000] {logging_mixin.py:188} INFO - [2024-03-29T17:10:42.662+0000] {dagbag.py:540} INFO - Filling up the DagBag from /opt/airflow/dags/emr_add_step_dag.py
[2024-03-29T17:10:42.893+0000] {logging_mixin.py:188} INFO - [2024-03-29T17:10:42.890+0000] {dagbag.py:350} ERROR - Failed to import: /opt/airflow/dags/emr_add_step_dag.py
Traceback (most recent call last):
  File "/home/airflow/.local/lib/python3.8/site-packages/dagfactory/dagfactory.py", line 71, in _load_config
    config: Dict[str, Any] = yaml.load(
  File "/home/airflow/.local/lib/python3.8/site-packages/yaml/__init__.py", line 81, in load
    return loader.get_single_data()
  File "/home/airflow/.local/lib/python3.8/site-packages/yaml/constructor.py", line 51, in get_single_data
    return self.construct_document(node)
  File "/home/airflow/.local/lib/python3.8/site-packages/yaml/constructor.py", line 60, in construct_document
    for dummy in generator:
  File "/home/airflow/.local/lib/python3.8/site-packages/yaml/constructor.py", line 413, in construct_yaml_map
    value = self.construct_mapping(node)
  File "/home/airflow/.local/lib/python3.8/site-packages/yaml/constructor.py", line 218, in construct_mapping
    return super().construct_mapping(node, deep=deep)
  File "/home/airflow/.local/lib/python3.8/site-packages/yaml/constructor.py", line 141, in construct_mapping
    raise ConstructorError("while constructing a mapping", node.start_mark,
yaml.constructor.ConstructorError: while constructing a mapping
  in "/opt/airflow/yaml/dag_definition_ex1.yaml", line 37, column 20
found unhashable key
  in "/opt/airflow/yaml/dag_definition_ex1.yaml", line 37, column 21

The above exception was the direct cause of the following exception:

Traceback (most recent call last):
  File "/home/airflow/.local/lib/python3.8/site-packages/airflow/models/dagbag.py", line 346, in parse
    loader.exec_module(new_module)
  File "<frozen importlib._bootstrap_external>", line 843, in exec_module
  File "<frozen importlib._bootstrap>", line 219, in _call_with_frames_removed
  File "/opt/airflow/dags/emr_add_step_dag.py", line 45, in <module>
    dag_factory = dagfactory.DagFactory(
  File "/home/airflow/.local/lib/python3.8/site-packages/dagfactory/dagfactory.py", line 39, in __init__
    self.config: Dict[str, Any] = DagFactory._load_config(
  File "/home/airflow/.local/lib/python3.8/site-packages/dagfactory/dagfactory.py", line 76, in _load_config
    raise DagFactoryConfigException("Invalid DAG Factory config file") from err
dagfactory.exceptions.DagFactoryConfigException: Invalid DAG Factory config file
[2024-03-29T17:10:42.893+0000] {processor.py:842} WARNING - No viable dags retrieved from /opt/airflow/dags/emr_add_step_dag.py
[2024-03-29T17:10:42.914+0000] {processor.py:183} INFO - Processing /opt/airflow/dags/emr_add_step_dag.py took 0.257 seconds
[2024-03-29T17:11:12.955+0000] {processor.py:161} INFO - Started process (PID=112) to work on /opt/airflow/dags/emr_add_step_dag.py
[2024-03-29T17:11:12.956+0000] {processor.py:830} INFO - Processing file /opt/airflow/dags/emr_add_step_dag.py for tasks to queue
[2024-03-29T17:11:12.958+0000] {logging_mixin.py:188} INFO - [2024-03-29T17:11:12.957+0000] {dagbag.py:540} INFO - Filling up the DagBag from /opt/airflow/dags/emr_add_step_dag.py
[2024-03-29T17:11:13.202+0000] {logging_mixin.py:188} INFO - [2024-03-29T17:11:13.200+0000] {dagbag.py:350} ERROR - Failed to import: /opt/airflow/dags/emr_add_step_dag.py
Traceback (most recent call last):
  File "/home/airflow/.local/lib/python3.8/site-packages/dagfactory/dagfactory.py", line 71, in _load_config
    config: Dict[str, Any] = yaml.load(
  File "/home/airflow/.local/lib/python3.8/site-packages/yaml/__init__.py", line 81, in load
    return loader.get_single_data()
  File "/home/airflow/.local/lib/python3.8/site-packages/yaml/constructor.py", line 51, in get_single_data
    return self.construct_document(node)
  File "/home/airflow/.local/lib/python3.8/site-packages/yaml/constructor.py", line 60, in construct_document
    for dummy in generator:
  File "/home/airflow/.local/lib/python3.8/site-packages/yaml/constructor.py", line 413, in construct_yaml_map
    value = self.construct_mapping(node)
  File "/home/airflow/.local/lib/python3.8/site-packages/yaml/constructor.py", line 218, in construct_mapping
    return super().construct_mapping(node, deep=deep)
  File "/home/airflow/.local/lib/python3.8/site-packages/yaml/constructor.py", line 141, in construct_mapping
    raise ConstructorError("while constructing a mapping", node.start_mark,
yaml.constructor.ConstructorError: while constructing a mapping
  in "/opt/airflow/yaml/dag_definition_ex1.yaml", line 37, column 20
found unhashable key
  in "/opt/airflow/yaml/dag_definition_ex1.yaml", line 37, column 21

The above exception was the direct cause of the following exception:

Traceback (most recent call last):
  File "/home/airflow/.local/lib/python3.8/site-packages/airflow/models/dagbag.py", line 346, in parse
    loader.exec_module(new_module)
  File "<frozen importlib._bootstrap_external>", line 843, in exec_module
  File "<frozen importlib._bootstrap>", line 219, in _call_with_frames_removed
  File "/opt/airflow/dags/emr_add_step_dag.py", line 45, in <module>
    dag_factory = dagfactory.DagFactory(
  File "/home/airflow/.local/lib/python3.8/site-packages/dagfactory/dagfactory.py", line 39, in __init__
    self.config: Dict[str, Any] = DagFactory._load_config(
  File "/home/airflow/.local/lib/python3.8/site-packages/dagfactory/dagfactory.py", line 76, in _load_config
    raise DagFactoryConfigException("Invalid DAG Factory config file") from err
dagfactory.exceptions.DagFactoryConfigException: Invalid DAG Factory config file
[2024-03-29T17:11:13.202+0000] {processor.py:842} WARNING - No viable dags retrieved from /opt/airflow/dags/emr_add_step_dag.py
[2024-03-29T17:11:13.222+0000] {processor.py:183} INFO - Processing /opt/airflow/dags/emr_add_step_dag.py took 0.269 seconds
[2024-03-29T17:11:43.293+0000] {processor.py:161} INFO - Started process (PID=120) to work on /opt/airflow/dags/emr_add_step_dag.py
[2024-03-29T17:11:43.294+0000] {processor.py:830} INFO - Processing file /opt/airflow/dags/emr_add_step_dag.py for tasks to queue
[2024-03-29T17:11:43.296+0000] {logging_mixin.py:188} INFO - [2024-03-29T17:11:43.295+0000] {dagbag.py:540} INFO - Filling up the DagBag from /opt/airflow/dags/emr_add_step_dag.py
[2024-03-29T17:11:43.521+0000] {logging_mixin.py:188} INFO - [2024-03-29T17:11:43.518+0000] {dagbag.py:350} ERROR - Failed to import: /opt/airflow/dags/emr_add_step_dag.py
Traceback (most recent call last):
  File "/home/airflow/.local/lib/python3.8/site-packages/dagfactory/dagfactory.py", line 71, in _load_config
    config: Dict[str, Any] = yaml.load(
  File "/home/airflow/.local/lib/python3.8/site-packages/yaml/__init__.py", line 81, in load
    return loader.get_single_data()
  File "/home/airflow/.local/lib/python3.8/site-packages/yaml/constructor.py", line 51, in get_single_data
    return self.construct_document(node)
  File "/home/airflow/.local/lib/python3.8/site-packages/yaml/constructor.py", line 60, in construct_document
    for dummy in generator:
  File "/home/airflow/.local/lib/python3.8/site-packages/yaml/constructor.py", line 413, in construct_yaml_map
    value = self.construct_mapping(node)
  File "/home/airflow/.local/lib/python3.8/site-packages/yaml/constructor.py", line 218, in construct_mapping
    return super().construct_mapping(node, deep=deep)
  File "/home/airflow/.local/lib/python3.8/site-packages/yaml/constructor.py", line 141, in construct_mapping
    raise ConstructorError("while constructing a mapping", node.start_mark,
yaml.constructor.ConstructorError: while constructing a mapping
  in "/opt/airflow/yaml/dag_definition_ex1.yaml", line 37, column 20
found unhashable key
  in "/opt/airflow/yaml/dag_definition_ex1.yaml", line 37, column 21

The above exception was the direct cause of the following exception:

Traceback (most recent call last):
  File "/home/airflow/.local/lib/python3.8/site-packages/airflow/models/dagbag.py", line 346, in parse
    loader.exec_module(new_module)
  File "<frozen importlib._bootstrap_external>", line 843, in exec_module
  File "<frozen importlib._bootstrap>", line 219, in _call_with_frames_removed
  File "/opt/airflow/dags/emr_add_step_dag.py", line 45, in <module>
    dag_factory = dagfactory.DagFactory(
  File "/home/airflow/.local/lib/python3.8/site-packages/dagfactory/dagfactory.py", line 39, in __init__
    self.config: Dict[str, Any] = DagFactory._load_config(
  File "/home/airflow/.local/lib/python3.8/site-packages/dagfactory/dagfactory.py", line 76, in _load_config
    raise DagFactoryConfigException("Invalid DAG Factory config file") from err
dagfactory.exceptions.DagFactoryConfigException: Invalid DAG Factory config file
[2024-03-29T17:11:43.522+0000] {processor.py:842} WARNING - No viable dags retrieved from /opt/airflow/dags/emr_add_step_dag.py
[2024-03-29T17:11:43.543+0000] {processor.py:183} INFO - Processing /opt/airflow/dags/emr_add_step_dag.py took 0.252 seconds
[2024-03-29T17:25:09.022+0000] {processor.py:161} INFO - Started process (PID=39) to work on /opt/airflow/dags/emr_add_step_dag.py
[2024-03-29T17:25:09.023+0000] {processor.py:830} INFO - Processing file /opt/airflow/dags/emr_add_step_dag.py for tasks to queue
[2024-03-29T17:25:09.026+0000] {logging_mixin.py:188} INFO - [2024-03-29T17:25:09.025+0000] {dagbag.py:540} INFO - Filling up the DagBag from /opt/airflow/dags/emr_add_step_dag.py
[2024-03-29T17:25:10.014+0000] {logging_mixin.py:188} INFO - [2024-03-29T17:25:10.012+0000] {dagbag.py:350} ERROR - Failed to import: /opt/airflow/dags/emr_add_step_dag.py
Traceback (most recent call last):
  File "/home/airflow/.local/lib/python3.8/site-packages/dagfactory/dagfactory.py", line 114, in build_dags
    dag: Dict[str, Union[str, DAG]] = dag_builder.build()
  File "/home/airflow/.local/lib/python3.8/site-packages/dagfactory/dagbuilder.py", line 718, in build
    dag_params: Dict[str, Any] = self.get_dag_params()
  File "/home/airflow/.local/lib/python3.8/site-packages/dagfactory/dagbuilder.py", line 251, in get_dag_params
    dag_params["on_success_callback"]: Callable = utils.get_python_callable(
  File "/home/airflow/.local/lib/python3.8/site-packages/dagfactory/utils.py", line 133, in get_python_callable
    spec.loader.exec_module(module)
  File "<frozen importlib._bootstrap_external>", line 839, in exec_module
  File "<frozen importlib._bootstrap_external>", line 975, in get_code
  File "<frozen importlib._bootstrap_external>", line 1032, in get_data
FileNotFoundError: [Errno 2] No such file or directory: '/usr/local/airflow/dags/print_hello.py'

The above exception was the direct cause of the following exception:

Traceback (most recent call last):
  File "/home/airflow/.local/lib/python3.8/site-packages/airflow/models/dagbag.py", line 346, in parse
    loader.exec_module(new_module)
  File "<frozen importlib._bootstrap_external>", line 843, in exec_module
  File "<frozen importlib._bootstrap>", line 219, in _call_with_frames_removed
  File "/opt/airflow/dags/emr_add_step_dag.py", line 48, in <module>
    dag_factory.clean_dags(globals())
  File "/home/airflow/.local/lib/python3.8/site-packages/dagfactory/dagfactory.py", line 152, in clean_dags
    dags: Dict[str, Any] = self.build_dags()
  File "/home/airflow/.local/lib/python3.8/site-packages/dagfactory/dagfactory.py", line 117, in build_dags
    raise DagFactoryException(
dagfactory.exceptions.DagFactoryException: Failed to generate dag example_dag1. verify config is correct
[2024-03-29T17:25:10.015+0000] {processor.py:842} WARNING - No viable dags retrieved from /opt/airflow/dags/emr_add_step_dag.py
[2024-03-29T17:25:10.028+0000] {processor.py:183} INFO - Processing /opt/airflow/dags/emr_add_step_dag.py took 1.009 seconds
[2024-03-29T17:25:40.788+0000] {processor.py:161} INFO - Started process (PID=48) to work on /opt/airflow/dags/emr_add_step_dag.py
[2024-03-29T17:25:40.789+0000] {processor.py:830} INFO - Processing file /opt/airflow/dags/emr_add_step_dag.py for tasks to queue
[2024-03-29T17:25:40.790+0000] {logging_mixin.py:188} INFO - [2024-03-29T17:25:40.790+0000] {dagbag.py:540} INFO - Filling up the DagBag from /opt/airflow/dags/emr_add_step_dag.py
[2024-03-29T17:25:41.038+0000] {logging_mixin.py:188} INFO - [2024-03-29T17:25:41.035+0000] {dagbag.py:350} ERROR - Failed to import: /opt/airflow/dags/emr_add_step_dag.py
Traceback (most recent call last):
  File "/home/airflow/.local/lib/python3.8/site-packages/dagfactory/dagfactory.py", line 114, in build_dags
    dag: Dict[str, Union[str, DAG]] = dag_builder.build()
  File "/home/airflow/.local/lib/python3.8/site-packages/dagfactory/dagbuilder.py", line 718, in build
    dag_params: Dict[str, Any] = self.get_dag_params()
  File "/home/airflow/.local/lib/python3.8/site-packages/dagfactory/dagbuilder.py", line 251, in get_dag_params
    dag_params["on_success_callback"]: Callable = utils.get_python_callable(
  File "/home/airflow/.local/lib/python3.8/site-packages/dagfactory/utils.py", line 133, in get_python_callable
    spec.loader.exec_module(module)
  File "<frozen importlib._bootstrap_external>", line 839, in exec_module
  File "<frozen importlib._bootstrap_external>", line 975, in get_code
  File "<frozen importlib._bootstrap_external>", line 1032, in get_data
FileNotFoundError: [Errno 2] No such file or directory: '/usr/local/airflow/dags/print_hello.py'

The above exception was the direct cause of the following exception:

Traceback (most recent call last):
  File "/home/airflow/.local/lib/python3.8/site-packages/airflow/models/dagbag.py", line 346, in parse
    loader.exec_module(new_module)
  File "<frozen importlib._bootstrap_external>", line 843, in exec_module
  File "<frozen importlib._bootstrap>", line 219, in _call_with_frames_removed
  File "/opt/airflow/dags/emr_add_step_dag.py", line 48, in <module>
    dag_factory.clean_dags(globals())
  File "/home/airflow/.local/lib/python3.8/site-packages/dagfactory/dagfactory.py", line 152, in clean_dags
    dags: Dict[str, Any] = self.build_dags()
  File "/home/airflow/.local/lib/python3.8/site-packages/dagfactory/dagfactory.py", line 117, in build_dags
    raise DagFactoryException(
dagfactory.exceptions.DagFactoryException: Failed to generate dag example_dag1. verify config is correct
[2024-03-29T17:25:41.038+0000] {processor.py:842} WARNING - No viable dags retrieved from /opt/airflow/dags/emr_add_step_dag.py
[2024-03-29T17:25:41.059+0000] {processor.py:183} INFO - Processing /opt/airflow/dags/emr_add_step_dag.py took 0.275 seconds
[2024-03-29T17:26:11.164+0000] {processor.py:161} INFO - Started process (PID=56) to work on /opt/airflow/dags/emr_add_step_dag.py
[2024-03-29T17:26:11.165+0000] {processor.py:830} INFO - Processing file /opt/airflow/dags/emr_add_step_dag.py for tasks to queue
[2024-03-29T17:26:11.166+0000] {logging_mixin.py:188} INFO - [2024-03-29T17:26:11.166+0000] {dagbag.py:540} INFO - Filling up the DagBag from /opt/airflow/dags/emr_add_step_dag.py
[2024-03-29T17:26:11.408+0000] {logging_mixin.py:188} WARNING - /home/airflow/.local/lib/python3.8/site-packages/airflow/models/baseoperator.py:437 RemovedInAirflow3Warning: provide_context is deprecated as of 2.0 and is no longer required
[2024-03-29T17:26:11.411+0000] {logging_mixin.py:188} INFO - [2024-03-29T17:26:11.409+0000] {dagbag.py:350} ERROR - Failed to import: /opt/airflow/dags/emr_add_step_dag.py
Traceback (most recent call last):
  File "/home/airflow/.local/lib/python3.8/site-packages/dagfactory/dagbuilder.py", line 617, in make_task
    operator_obj(**task_params)
  File "/home/airflow/.local/lib/python3.8/site-packages/airflow/models/baseoperator.py", line 437, in apply_defaults
    result = func(self, **kwargs, default_args=default_args)
  File "/home/airflow/.local/lib/python3.8/site-packages/airflow/models/baseoperator.py", line 437, in apply_defaults
    result = func(self, **kwargs, default_args=default_args)
  File "/home/airflow/.local/lib/python3.8/site-packages/airflow/operators/python.py", line 187, in __init__
    raise AirflowException("`python_callable` param must be callable")
airflow.exceptions.AirflowException: `python_callable` param must be callable

The above exception was the direct cause of the following exception:

Traceback (most recent call last):
  File "/home/airflow/.local/lib/python3.8/site-packages/dagfactory/dagfactory.py", line 114, in build_dags
    dag: Dict[str, Union[str, DAG]] = dag_builder.build()
  File "/home/airflow/.local/lib/python3.8/site-packages/dagfactory/dagbuilder.py", line 879, in build
    task: Union[BaseOperator, MappedOperator] = DagBuilder.make_task(
  File "/home/airflow/.local/lib/python3.8/site-packages/dagfactory/dagbuilder.py", line 622, in make_task
    raise DagFactoryException(f"Failed to create {operator_obj} task") from err
dagfactory.exceptions.DagFactoryException: Failed to create <class 'airflow.operators.python.BranchPythonOperator'> task

The above exception was the direct cause of the following exception:

Traceback (most recent call last):
  File "/home/airflow/.local/lib/python3.8/site-packages/airflow/models/dagbag.py", line 346, in parse
    loader.exec_module(new_module)
  File "<frozen importlib._bootstrap_external>", line 843, in exec_module
  File "<frozen importlib._bootstrap>", line 219, in _call_with_frames_removed
  File "/opt/airflow/dags/emr_add_step_dag.py", line 48, in <module>
    dag_factory.clean_dags(globals())
  File "/home/airflow/.local/lib/python3.8/site-packages/dagfactory/dagfactory.py", line 152, in clean_dags
    dags: Dict[str, Any] = self.build_dags()
  File "/home/airflow/.local/lib/python3.8/site-packages/dagfactory/dagfactory.py", line 117, in build_dags
    raise DagFactoryException(
dagfactory.exceptions.DagFactoryException: Failed to generate dag example_dag1. verify config is correct
[2024-03-29T17:26:11.412+0000] {processor.py:842} WARNING - No viable dags retrieved from /opt/airflow/dags/emr_add_step_dag.py
[2024-03-29T17:26:11.424+0000] {processor.py:183} INFO - Processing /opt/airflow/dags/emr_add_step_dag.py took 0.263 seconds
[2024-03-29T17:27:17.603+0000] {processor.py:161} INFO - Started process (PID=39) to work on /opt/airflow/dags/emr_add_step_dag.py
[2024-03-29T17:27:17.604+0000] {processor.py:830} INFO - Processing file /opt/airflow/dags/emr_add_step_dag.py for tasks to queue
[2024-03-29T17:27:17.606+0000] {logging_mixin.py:188} INFO - [2024-03-29T17:27:17.606+0000] {dagbag.py:540} INFO - Filling up the DagBag from /opt/airflow/dags/emr_add_step_dag.py
[2024-03-29T17:27:18.589+0000] {logging_mixin.py:188} WARNING - /home/airflow/.local/lib/python3.8/site-packages/airflow/models/baseoperator.py:437 RemovedInAirflow3Warning: provide_context is deprecated as of 2.0 and is no longer required
[2024-03-29T17:27:18.593+0000] {logging_mixin.py:188} INFO - [2024-03-29T17:27:18.590+0000] {dagbag.py:350} ERROR - Failed to import: /opt/airflow/dags/emr_add_step_dag.py
Traceback (most recent call last):
  File "/home/airflow/.local/lib/python3.8/site-packages/dagfactory/dagbuilder.py", line 617, in make_task
    operator_obj(**task_params)
  File "/home/airflow/.local/lib/python3.8/site-packages/airflow/models/baseoperator.py", line 437, in apply_defaults
    result = func(self, **kwargs, default_args=default_args)
  File "/home/airflow/.local/lib/python3.8/site-packages/airflow/models/baseoperator.py", line 437, in apply_defaults
    result = func(self, **kwargs, default_args=default_args)
  File "/home/airflow/.local/lib/python3.8/site-packages/airflow/operators/python.py", line 187, in __init__
    raise AirflowException("`python_callable` param must be callable")
airflow.exceptions.AirflowException: `python_callable` param must be callable

The above exception was the direct cause of the following exception:

Traceback (most recent call last):
  File "/home/airflow/.local/lib/python3.8/site-packages/dagfactory/dagfactory.py", line 114, in build_dags
    dag: Dict[str, Union[str, DAG]] = dag_builder.build()
  File "/home/airflow/.local/lib/python3.8/site-packages/dagfactory/dagbuilder.py", line 879, in build
    task: Union[BaseOperator, MappedOperator] = DagBuilder.make_task(
  File "/home/airflow/.local/lib/python3.8/site-packages/dagfactory/dagbuilder.py", line 622, in make_task
    raise DagFactoryException(f"Failed to create {operator_obj} task") from err
dagfactory.exceptions.DagFactoryException: Failed to create <class 'airflow.operators.python.BranchPythonOperator'> task

The above exception was the direct cause of the following exception:

Traceback (most recent call last):
  File "/home/airflow/.local/lib/python3.8/site-packages/airflow/models/dagbag.py", line 346, in parse
    loader.exec_module(new_module)
  File "<frozen importlib._bootstrap_external>", line 843, in exec_module
  File "<frozen importlib._bootstrap>", line 219, in _call_with_frames_removed
  File "/opt/airflow/dags/emr_add_step_dag.py", line 48, in <module>
    dag_factory.clean_dags(globals())
  File "/home/airflow/.local/lib/python3.8/site-packages/dagfactory/dagfactory.py", line 152, in clean_dags
    dags: Dict[str, Any] = self.build_dags()
  File "/home/airflow/.local/lib/python3.8/site-packages/dagfactory/dagfactory.py", line 117, in build_dags
    raise DagFactoryException(
dagfactory.exceptions.DagFactoryException: Failed to generate dag example_dag1. verify config is correct
[2024-03-29T17:27:18.593+0000] {processor.py:842} WARNING - No viable dags retrieved from /opt/airflow/dags/emr_add_step_dag.py
[2024-03-29T17:27:18.618+0000] {processor.py:183} INFO - Processing /opt/airflow/dags/emr_add_step_dag.py took 1.018 seconds
[2024-03-29T17:27:49.439+0000] {processor.py:161} INFO - Started process (PID=48) to work on /opt/airflow/dags/emr_add_step_dag.py
[2024-03-29T17:27:49.440+0000] {processor.py:830} INFO - Processing file /opt/airflow/dags/emr_add_step_dag.py for tasks to queue
[2024-03-29T17:27:49.441+0000] {logging_mixin.py:188} INFO - [2024-03-29T17:27:49.441+0000] {dagbag.py:540} INFO - Filling up the DagBag from /opt/airflow/dags/emr_add_step_dag.py
[2024-03-29T17:27:49.677+0000] {logging_mixin.py:188} WARNING - /home/airflow/.local/lib/python3.8/site-packages/airflow/models/baseoperator.py:437 RemovedInAirflow3Warning: provide_context is deprecated as of 2.0 and is no longer required
[2024-03-29T17:27:49.680+0000] {logging_mixin.py:188} INFO - [2024-03-29T17:27:49.678+0000] {dagbag.py:350} ERROR - Failed to import: /opt/airflow/dags/emr_add_step_dag.py
Traceback (most recent call last):
  File "/home/airflow/.local/lib/python3.8/site-packages/dagfactory/dagbuilder.py", line 617, in make_task
    operator_obj(**task_params)
  File "/home/airflow/.local/lib/python3.8/site-packages/airflow/models/baseoperator.py", line 437, in apply_defaults
    result = func(self, **kwargs, default_args=default_args)
  File "/home/airflow/.local/lib/python3.8/site-packages/airflow/models/baseoperator.py", line 437, in apply_defaults
    result = func(self, **kwargs, default_args=default_args)
  File "/home/airflow/.local/lib/python3.8/site-packages/airflow/operators/python.py", line 187, in __init__
    raise AirflowException("`python_callable` param must be callable")
airflow.exceptions.AirflowException: `python_callable` param must be callable

The above exception was the direct cause of the following exception:

Traceback (most recent call last):
  File "/home/airflow/.local/lib/python3.8/site-packages/dagfactory/dagfactory.py", line 114, in build_dags
    dag: Dict[str, Union[str, DAG]] = dag_builder.build()
  File "/home/airflow/.local/lib/python3.8/site-packages/dagfactory/dagbuilder.py", line 879, in build
    task: Union[BaseOperator, MappedOperator] = DagBuilder.make_task(
  File "/home/airflow/.local/lib/python3.8/site-packages/dagfactory/dagbuilder.py", line 622, in make_task
    raise DagFactoryException(f"Failed to create {operator_obj} task") from err
dagfactory.exceptions.DagFactoryException: Failed to create <class 'airflow.operators.python.BranchPythonOperator'> task

The above exception was the direct cause of the following exception:

Traceback (most recent call last):
  File "/home/airflow/.local/lib/python3.8/site-packages/airflow/models/dagbag.py", line 346, in parse
    loader.exec_module(new_module)
  File "<frozen importlib._bootstrap_external>", line 843, in exec_module
  File "<frozen importlib._bootstrap>", line 219, in _call_with_frames_removed
  File "/opt/airflow/dags/emr_add_step_dag.py", line 48, in <module>
    dag_factory.clean_dags(globals())
  File "/home/airflow/.local/lib/python3.8/site-packages/dagfactory/dagfactory.py", line 152, in clean_dags
    dags: Dict[str, Any] = self.build_dags()
  File "/home/airflow/.local/lib/python3.8/site-packages/dagfactory/dagfactory.py", line 117, in build_dags
    raise DagFactoryException(
dagfactory.exceptions.DagFactoryException: Failed to generate dag example_dag1. verify config is correct
[2024-03-29T17:27:49.681+0000] {processor.py:842} WARNING - No viable dags retrieved from /opt/airflow/dags/emr_add_step_dag.py
[2024-03-29T17:27:49.700+0000] {processor.py:183} INFO - Processing /opt/airflow/dags/emr_add_step_dag.py took 0.264 seconds
[2024-03-29T17:28:19.809+0000] {processor.py:161} INFO - Started process (PID=56) to work on /opt/airflow/dags/emr_add_step_dag.py
[2024-03-29T17:28:19.810+0000] {processor.py:830} INFO - Processing file /opt/airflow/dags/emr_add_step_dag.py for tasks to queue
[2024-03-29T17:28:19.812+0000] {logging_mixin.py:188} INFO - [2024-03-29T17:28:19.811+0000] {dagbag.py:540} INFO - Filling up the DagBag from /opt/airflow/dags/emr_add_step_dag.py
[2024-03-29T17:28:20.055+0000] {logging_mixin.py:188} WARNING - /home/airflow/.local/lib/python3.8/site-packages/airflow/models/baseoperator.py:437 RemovedInAirflow3Warning: provide_context is deprecated as of 2.0 and is no longer required
[2024-03-29T17:28:20.058+0000] {logging_mixin.py:188} INFO - [2024-03-29T17:28:20.055+0000] {dagbag.py:350} ERROR - Failed to import: /opt/airflow/dags/emr_add_step_dag.py
Traceback (most recent call last):
  File "/home/airflow/.local/lib/python3.8/site-packages/dagfactory/dagbuilder.py", line 617, in make_task
    operator_obj(**task_params)
  File "/home/airflow/.local/lib/python3.8/site-packages/airflow/models/baseoperator.py", line 437, in apply_defaults
    result = func(self, **kwargs, default_args=default_args)
  File "/home/airflow/.local/lib/python3.8/site-packages/airflow/models/baseoperator.py", line 437, in apply_defaults
    result = func(self, **kwargs, default_args=default_args)
  File "/home/airflow/.local/lib/python3.8/site-packages/airflow/operators/python.py", line 187, in __init__
    raise AirflowException("`python_callable` param must be callable")
airflow.exceptions.AirflowException: `python_callable` param must be callable

The above exception was the direct cause of the following exception:

Traceback (most recent call last):
  File "/home/airflow/.local/lib/python3.8/site-packages/dagfactory/dagfactory.py", line 114, in build_dags
    dag: Dict[str, Union[str, DAG]] = dag_builder.build()
  File "/home/airflow/.local/lib/python3.8/site-packages/dagfactory/dagbuilder.py", line 879, in build
    task: Union[BaseOperator, MappedOperator] = DagBuilder.make_task(
  File "/home/airflow/.local/lib/python3.8/site-packages/dagfactory/dagbuilder.py", line 622, in make_task
    raise DagFactoryException(f"Failed to create {operator_obj} task") from err
dagfactory.exceptions.DagFactoryException: Failed to create <class 'airflow.operators.python.BranchPythonOperator'> task

The above exception was the direct cause of the following exception:

Traceback (most recent call last):
  File "/home/airflow/.local/lib/python3.8/site-packages/airflow/models/dagbag.py", line 346, in parse
    loader.exec_module(new_module)
  File "<frozen importlib._bootstrap_external>", line 843, in exec_module
  File "<frozen importlib._bootstrap>", line 219, in _call_with_frames_removed
  File "/opt/airflow/dags/emr_add_step_dag.py", line 48, in <module>
    dag_factory.clean_dags(globals())
  File "/home/airflow/.local/lib/python3.8/site-packages/dagfactory/dagfactory.py", line 152, in clean_dags
    dags: Dict[str, Any] = self.build_dags()
  File "/home/airflow/.local/lib/python3.8/site-packages/dagfactory/dagfactory.py", line 117, in build_dags
    raise DagFactoryException(
dagfactory.exceptions.DagFactoryException: Failed to generate dag example_dag1. verify config is correct
[2024-03-29T17:28:20.059+0000] {processor.py:842} WARNING - No viable dags retrieved from /opt/airflow/dags/emr_add_step_dag.py
[2024-03-29T17:28:20.074+0000] {processor.py:183} INFO - Processing /opt/airflow/dags/emr_add_step_dag.py took 0.267 seconds
[2024-03-29T17:35:14.551+0000] {processor.py:161} INFO - Started process (PID=39) to work on /opt/airflow/dags/emr_add_step_dag.py
[2024-03-29T17:35:14.552+0000] {processor.py:830} INFO - Processing file /opt/airflow/dags/emr_add_step_dag.py for tasks to queue
[2024-03-29T17:35:14.554+0000] {logging_mixin.py:188} INFO - [2024-03-29T17:35:14.554+0000] {dagbag.py:540} INFO - Filling up the DagBag from /opt/airflow/dags/emr_add_step_dag.py
[2024-03-29T17:35:15.593+0000] {logging_mixin.py:188} WARNING - /home/airflow/.local/lib/python3.8/site-packages/airflow/models/baseoperator.py:437 RemovedInAirflow3Warning: provide_context is deprecated as of 2.0 and is no longer required
[2024-03-29T17:35:15.596+0000] {logging_mixin.py:188} INFO - [2024-03-29T17:35:15.594+0000] {dagbag.py:350} ERROR - Failed to import: /opt/airflow/dags/emr_add_step_dag.py
Traceback (most recent call last):
  File "/home/airflow/.local/lib/python3.8/site-packages/dagfactory/dagfactory.py", line 114, in build_dags
    dag: Dict[str, Union[str, DAG]] = dag_builder.build()
  File "/home/airflow/.local/lib/python3.8/site-packages/dagfactory/dagbuilder.py", line 856, in build
    operator: str = task_conf["operator"]
KeyError: 'operator'

The above exception was the direct cause of the following exception:

Traceback (most recent call last):
  File "/home/airflow/.local/lib/python3.8/site-packages/airflow/models/dagbag.py", line 346, in parse
    loader.exec_module(new_module)
  File "<frozen importlib._bootstrap_external>", line 843, in exec_module
  File "<frozen importlib._bootstrap>", line 219, in _call_with_frames_removed
  File "/opt/airflow/dags/emr_add_step_dag.py", line 27, in <module>
    dag_factory.clean_dags(globals())
  File "/home/airflow/.local/lib/python3.8/site-packages/dagfactory/dagfactory.py", line 152, in clean_dags
    dags: Dict[str, Any] = self.build_dags()
  File "/home/airflow/.local/lib/python3.8/site-packages/dagfactory/dagfactory.py", line 117, in build_dags
    raise DagFactoryException(
dagfactory.exceptions.DagFactoryException: Failed to generate dag example_dag1. verify config is correct
[2024-03-29T17:35:15.597+0000] {processor.py:842} WARNING - No viable dags retrieved from /opt/airflow/dags/emr_add_step_dag.py
[2024-03-29T17:35:15.610+0000] {processor.py:183} INFO - Processing /opt/airflow/dags/emr_add_step_dag.py took 1.062 seconds
[2024-03-29T17:35:46.364+0000] {processor.py:161} INFO - Started process (PID=48) to work on /opt/airflow/dags/emr_add_step_dag.py
[2024-03-29T17:35:46.365+0000] {processor.py:830} INFO - Processing file /opt/airflow/dags/emr_add_step_dag.py for tasks to queue
[2024-03-29T17:35:46.366+0000] {logging_mixin.py:188} INFO - [2024-03-29T17:35:46.366+0000] {dagbag.py:540} INFO - Filling up the DagBag from /opt/airflow/dags/emr_add_step_dag.py
[2024-03-29T17:35:46.644+0000] {logging_mixin.py:188} WARNING - /home/airflow/.local/lib/python3.8/site-packages/airflow/models/baseoperator.py:437 RemovedInAirflow3Warning: provide_context is deprecated as of 2.0 and is no longer required
[2024-03-29T17:35:46.647+0000] {logging_mixin.py:188} INFO - [2024-03-29T17:35:46.645+0000] {dagbag.py:350} ERROR - Failed to import: /opt/airflow/dags/emr_add_step_dag.py
Traceback (most recent call last):
  File "/home/airflow/.local/lib/python3.8/site-packages/dagfactory/dagfactory.py", line 114, in build_dags
    dag: Dict[str, Union[str, DAG]] = dag_builder.build()
  File "/home/airflow/.local/lib/python3.8/site-packages/dagfactory/dagbuilder.py", line 856, in build
    operator: str = task_conf["operator"]
KeyError: 'operator'

The above exception was the direct cause of the following exception:

Traceback (most recent call last):
  File "/home/airflow/.local/lib/python3.8/site-packages/airflow/models/dagbag.py", line 346, in parse
    loader.exec_module(new_module)
  File "<frozen importlib._bootstrap_external>", line 843, in exec_module
  File "<frozen importlib._bootstrap>", line 219, in _call_with_frames_removed
  File "/opt/airflow/dags/emr_add_step_dag.py", line 27, in <module>
    dag_factory.clean_dags(globals())
  File "/home/airflow/.local/lib/python3.8/site-packages/dagfactory/dagfactory.py", line 152, in clean_dags
    dags: Dict[str, Any] = self.build_dags()
  File "/home/airflow/.local/lib/python3.8/site-packages/dagfactory/dagfactory.py", line 117, in build_dags
    raise DagFactoryException(
dagfactory.exceptions.DagFactoryException: Failed to generate dag example_dag1. verify config is correct
[2024-03-29T17:35:46.648+0000] {processor.py:842} WARNING - No viable dags retrieved from /opt/airflow/dags/emr_add_step_dag.py
[2024-03-29T17:35:46.669+0000] {processor.py:183} INFO - Processing /opt/airflow/dags/emr_add_step_dag.py took 0.308 seconds
[2024-03-29T17:36:16.694+0000] {processor.py:161} INFO - Started process (PID=56) to work on /opt/airflow/dags/emr_add_step_dag.py
[2024-03-29T17:36:16.695+0000] {processor.py:830} INFO - Processing file /opt/airflow/dags/emr_add_step_dag.py for tasks to queue
[2024-03-29T17:36:16.696+0000] {logging_mixin.py:188} INFO - [2024-03-29T17:36:16.696+0000] {dagbag.py:540} INFO - Filling up the DagBag from /opt/airflow/dags/emr_add_step_dag.py
[2024-03-29T17:36:16.930+0000] {logging_mixin.py:188} WARNING - /home/airflow/.local/lib/python3.8/site-packages/airflow/models/baseoperator.py:437 RemovedInAirflow3Warning: provide_context is deprecated as of 2.0 and is no longer required
[2024-03-29T17:36:16.933+0000] {logging_mixin.py:188} INFO - [2024-03-29T17:36:16.931+0000] {dagbag.py:350} ERROR - Failed to import: /opt/airflow/dags/emr_add_step_dag.py
Traceback (most recent call last):
  File "/home/airflow/.local/lib/python3.8/site-packages/dagfactory/dagfactory.py", line 114, in build_dags
    dag: Dict[str, Union[str, DAG]] = dag_builder.build()
  File "/home/airflow/.local/lib/python3.8/site-packages/dagfactory/dagbuilder.py", line 856, in build
    operator: str = task_conf["operator"]
KeyError: 'operator'

The above exception was the direct cause of the following exception:

Traceback (most recent call last):
  File "/home/airflow/.local/lib/python3.8/site-packages/airflow/models/dagbag.py", line 346, in parse
    loader.exec_module(new_module)
  File "<frozen importlib._bootstrap_external>", line 843, in exec_module
  File "<frozen importlib._bootstrap>", line 219, in _call_with_frames_removed
  File "/opt/airflow/dags/emr_add_step_dag.py", line 27, in <module>
    dag_factory.clean_dags(globals())
  File "/home/airflow/.local/lib/python3.8/site-packages/dagfactory/dagfactory.py", line 152, in clean_dags
    dags: Dict[str, Any] = self.build_dags()
  File "/home/airflow/.local/lib/python3.8/site-packages/dagfactory/dagfactory.py", line 117, in build_dags
    raise DagFactoryException(
dagfactory.exceptions.DagFactoryException: Failed to generate dag example_dag1. verify config is correct
[2024-03-29T17:36:16.934+0000] {processor.py:842} WARNING - No viable dags retrieved from /opt/airflow/dags/emr_add_step_dag.py
[2024-03-29T17:36:16.946+0000] {processor.py:183} INFO - Processing /opt/airflow/dags/emr_add_step_dag.py took 0.255 seconds
[2024-03-29T17:36:47.004+0000] {processor.py:161} INFO - Started process (PID=64) to work on /opt/airflow/dags/emr_add_step_dag.py
[2024-03-29T17:36:47.005+0000] {processor.py:830} INFO - Processing file /opt/airflow/dags/emr_add_step_dag.py for tasks to queue
[2024-03-29T17:36:47.007+0000] {logging_mixin.py:188} INFO - [2024-03-29T17:36:47.006+0000] {dagbag.py:540} INFO - Filling up the DagBag from /opt/airflow/dags/emr_add_step_dag.py
[2024-03-29T17:36:47.245+0000] {logging_mixin.py:188} WARNING - /home/airflow/.local/lib/python3.8/site-packages/airflow/models/baseoperator.py:437 RemovedInAirflow3Warning: provide_context is deprecated as of 2.0 and is no longer required
[2024-03-29T17:36:47.247+0000] {logging_mixin.py:188} INFO - [2024-03-29T17:36:47.245+0000] {dagbag.py:350} ERROR - Failed to import: /opt/airflow/dags/emr_add_step_dag.py
Traceback (most recent call last):
  File "/home/airflow/.local/lib/python3.8/site-packages/dagfactory/dagfactory.py", line 114, in build_dags
    dag: Dict[str, Union[str, DAG]] = dag_builder.build()
  File "/home/airflow/.local/lib/python3.8/site-packages/dagfactory/dagbuilder.py", line 856, in build
    operator: str = task_conf["operator"]
KeyError: 'operator'

The above exception was the direct cause of the following exception:

Traceback (most recent call last):
  File "/home/airflow/.local/lib/python3.8/site-packages/airflow/models/dagbag.py", line 346, in parse
    loader.exec_module(new_module)
  File "<frozen importlib._bootstrap_external>", line 843, in exec_module
  File "<frozen importlib._bootstrap>", line 219, in _call_with_frames_removed
  File "/opt/airflow/dags/emr_add_step_dag.py", line 27, in <module>
    dag_factory.clean_dags(globals())
  File "/home/airflow/.local/lib/python3.8/site-packages/dagfactory/dagfactory.py", line 152, in clean_dags
    dags: Dict[str, Any] = self.build_dags()
  File "/home/airflow/.local/lib/python3.8/site-packages/dagfactory/dagfactory.py", line 117, in build_dags
    raise DagFactoryException(
dagfactory.exceptions.DagFactoryException: Failed to generate dag example_dag1. verify config is correct
[2024-03-29T17:36:47.248+0000] {processor.py:842} WARNING - No viable dags retrieved from /opt/airflow/dags/emr_add_step_dag.py
[2024-03-29T17:36:47.267+0000] {processor.py:183} INFO - Processing /opt/airflow/dags/emr_add_step_dag.py took 0.266 seconds
[2024-03-29T17:37:17.313+0000] {processor.py:161} INFO - Started process (PID=72) to work on /opt/airflow/dags/emr_add_step_dag.py
[2024-03-29T17:37:17.314+0000] {processor.py:830} INFO - Processing file /opt/airflow/dags/emr_add_step_dag.py for tasks to queue
[2024-03-29T17:37:17.315+0000] {logging_mixin.py:188} INFO - [2024-03-29T17:37:17.315+0000] {dagbag.py:540} INFO - Filling up the DagBag from /opt/airflow/dags/emr_add_step_dag.py
[2024-03-29T17:37:17.555+0000] {logging_mixin.py:188} WARNING - /home/airflow/.local/lib/python3.8/site-packages/airflow/models/baseoperator.py:437 RemovedInAirflow3Warning: provide_context is deprecated as of 2.0 and is no longer required
[2024-03-29T17:37:17.558+0000] {logging_mixin.py:188} INFO - [2024-03-29T17:37:17.556+0000] {dagbag.py:350} ERROR - Failed to import: /opt/airflow/dags/emr_add_step_dag.py
Traceback (most recent call last):
  File "/home/airflow/.local/lib/python3.8/site-packages/dagfactory/dagfactory.py", line 114, in build_dags
    dag: Dict[str, Union[str, DAG]] = dag_builder.build()
  File "/home/airflow/.local/lib/python3.8/site-packages/dagfactory/dagbuilder.py", line 856, in build
    operator: str = task_conf["operator"]
KeyError: 'operator'

The above exception was the direct cause of the following exception:

Traceback (most recent call last):
  File "/home/airflow/.local/lib/python3.8/site-packages/airflow/models/dagbag.py", line 346, in parse
    loader.exec_module(new_module)
  File "<frozen importlib._bootstrap_external>", line 843, in exec_module
  File "<frozen importlib._bootstrap>", line 219, in _call_with_frames_removed
  File "/opt/airflow/dags/emr_add_step_dag.py", line 27, in <module>
    dag_factory.clean_dags(globals())
  File "/home/airflow/.local/lib/python3.8/site-packages/dagfactory/dagfactory.py", line 152, in clean_dags
    dags: Dict[str, Any] = self.build_dags()
  File "/home/airflow/.local/lib/python3.8/site-packages/dagfactory/dagfactory.py", line 117, in build_dags
    raise DagFactoryException(
dagfactory.exceptions.DagFactoryException: Failed to generate dag example_dag1. verify config is correct
[2024-03-29T17:37:17.559+0000] {processor.py:842} WARNING - No viable dags retrieved from /opt/airflow/dags/emr_add_step_dag.py
[2024-03-29T17:37:17.573+0000] {processor.py:183} INFO - Processing /opt/airflow/dags/emr_add_step_dag.py took 0.262 seconds
[2024-03-29T17:37:47.630+0000] {processor.py:161} INFO - Started process (PID=80) to work on /opt/airflow/dags/emr_add_step_dag.py
[2024-03-29T17:37:47.631+0000] {processor.py:830} INFO - Processing file /opt/airflow/dags/emr_add_step_dag.py for tasks to queue
[2024-03-29T17:37:47.632+0000] {logging_mixin.py:188} INFO - [2024-03-29T17:37:47.632+0000] {dagbag.py:540} INFO - Filling up the DagBag from /opt/airflow/dags/emr_add_step_dag.py
[2024-03-29T17:37:47.886+0000] {logging_mixin.py:188} WARNING - /home/airflow/.local/lib/python3.8/site-packages/airflow/models/baseoperator.py:437 RemovedInAirflow3Warning: provide_context is deprecated as of 2.0 and is no longer required
[2024-03-29T17:37:47.889+0000] {logging_mixin.py:188} INFO - [2024-03-29T17:37:47.887+0000] {dagbag.py:350} ERROR - Failed to import: /opt/airflow/dags/emr_add_step_dag.py
Traceback (most recent call last):
  File "/home/airflow/.local/lib/python3.8/site-packages/dagfactory/dagfactory.py", line 114, in build_dags
    dag: Dict[str, Union[str, DAG]] = dag_builder.build()
  File "/home/airflow/.local/lib/python3.8/site-packages/dagfactory/dagbuilder.py", line 856, in build
    operator: str = task_conf["operator"]
KeyError: 'operator'

The above exception was the direct cause of the following exception:

Traceback (most recent call last):
  File "/home/airflow/.local/lib/python3.8/site-packages/airflow/models/dagbag.py", line 346, in parse
    loader.exec_module(new_module)
  File "<frozen importlib._bootstrap_external>", line 843, in exec_module
  File "<frozen importlib._bootstrap>", line 219, in _call_with_frames_removed
  File "/opt/airflow/dags/emr_add_step_dag.py", line 27, in <module>
    dag_factory.clean_dags(globals())
  File "/home/airflow/.local/lib/python3.8/site-packages/dagfactory/dagfactory.py", line 152, in clean_dags
    dags: Dict[str, Any] = self.build_dags()
  File "/home/airflow/.local/lib/python3.8/site-packages/dagfactory/dagfactory.py", line 117, in build_dags
    raise DagFactoryException(
dagfactory.exceptions.DagFactoryException: Failed to generate dag example_dag1. verify config is correct
[2024-03-29T17:37:47.889+0000] {processor.py:842} WARNING - No viable dags retrieved from /opt/airflow/dags/emr_add_step_dag.py
[2024-03-29T17:37:47.910+0000] {processor.py:183} INFO - Processing /opt/airflow/dags/emr_add_step_dag.py took 0.283 seconds
[2024-03-29T17:38:18.016+0000] {processor.py:161} INFO - Started process (PID=88) to work on /opt/airflow/dags/emr_add_step_dag.py
[2024-03-29T17:38:18.017+0000] {processor.py:830} INFO - Processing file /opt/airflow/dags/emr_add_step_dag.py for tasks to queue
[2024-03-29T17:38:18.019+0000] {logging_mixin.py:188} INFO - [2024-03-29T17:38:18.019+0000] {dagbag.py:540} INFO - Filling up the DagBag from /opt/airflow/dags/emr_add_step_dag.py
[2024-03-29T17:38:18.283+0000] {logging_mixin.py:188} WARNING - /home/airflow/.local/lib/python3.8/site-packages/airflow/models/baseoperator.py:437 RemovedInAirflow3Warning: provide_context is deprecated as of 2.0 and is no longer required
[2024-03-29T17:38:18.286+0000] {logging_mixin.py:188} INFO - [2024-03-29T17:38:18.284+0000] {dagbag.py:350} ERROR - Failed to import: /opt/airflow/dags/emr_add_step_dag.py
Traceback (most recent call last):
  File "/home/airflow/.local/lib/python3.8/site-packages/dagfactory/dagfactory.py", line 114, in build_dags
    dag: Dict[str, Union[str, DAG]] = dag_builder.build()
  File "/home/airflow/.local/lib/python3.8/site-packages/dagfactory/dagbuilder.py", line 856, in build
    operator: str = task_conf["operator"]
KeyError: 'operator'

The above exception was the direct cause of the following exception:

Traceback (most recent call last):
  File "/home/airflow/.local/lib/python3.8/site-packages/airflow/models/dagbag.py", line 346, in parse
    loader.exec_module(new_module)
  File "<frozen importlib._bootstrap_external>", line 843, in exec_module
  File "<frozen importlib._bootstrap>", line 219, in _call_with_frames_removed
  File "/opt/airflow/dags/emr_add_step_dag.py", line 27, in <module>
    dag_factory.clean_dags(globals())
  File "/home/airflow/.local/lib/python3.8/site-packages/dagfactory/dagfactory.py", line 152, in clean_dags
    dags: Dict[str, Any] = self.build_dags()
  File "/home/airflow/.local/lib/python3.8/site-packages/dagfactory/dagfactory.py", line 117, in build_dags
    raise DagFactoryException(
dagfactory.exceptions.DagFactoryException: Failed to generate dag example_dag1. verify config is correct
[2024-03-29T17:38:18.287+0000] {processor.py:842} WARNING - No viable dags retrieved from /opt/airflow/dags/emr_add_step_dag.py
[2024-03-29T17:38:18.309+0000] {processor.py:183} INFO - Processing /opt/airflow/dags/emr_add_step_dag.py took 0.296 seconds
[2024-03-29T17:38:49.223+0000] {processor.py:161} INFO - Started process (PID=96) to work on /opt/airflow/dags/emr_add_step_dag.py
[2024-03-29T17:38:49.224+0000] {processor.py:830} INFO - Processing file /opt/airflow/dags/emr_add_step_dag.py for tasks to queue
[2024-03-29T17:38:49.226+0000] {logging_mixin.py:188} INFO - [2024-03-29T17:38:49.225+0000] {dagbag.py:540} INFO - Filling up the DagBag from /opt/airflow/dags/emr_add_step_dag.py
[2024-03-29T17:38:49.473+0000] {logging_mixin.py:188} WARNING - /home/airflow/.local/lib/python3.8/site-packages/airflow/models/baseoperator.py:437 RemovedInAirflow3Warning: provide_context is deprecated as of 2.0 and is no longer required
[2024-03-29T17:38:49.475+0000] {logging_mixin.py:188} INFO - [2024-03-29T17:38:49.473+0000] {dagbag.py:350} ERROR - Failed to import: /opt/airflow/dags/emr_add_step_dag.py
Traceback (most recent call last):
  File "/home/airflow/.local/lib/python3.8/site-packages/dagfactory/dagfactory.py", line 114, in build_dags
    dag: Dict[str, Union[str, DAG]] = dag_builder.build()
  File "/home/airflow/.local/lib/python3.8/site-packages/dagfactory/dagbuilder.py", line 856, in build
    operator: str = task_conf["operator"]
KeyError: 'operator'

The above exception was the direct cause of the following exception:

Traceback (most recent call last):
  File "/home/airflow/.local/lib/python3.8/site-packages/airflow/models/dagbag.py", line 346, in parse
    loader.exec_module(new_module)
  File "<frozen importlib._bootstrap_external>", line 843, in exec_module
  File "<frozen importlib._bootstrap>", line 219, in _call_with_frames_removed
  File "/opt/airflow/dags/emr_add_step_dag.py", line 27, in <module>
    dag_factory.clean_dags(globals())
  File "/home/airflow/.local/lib/python3.8/site-packages/dagfactory/dagfactory.py", line 152, in clean_dags
    dags: Dict[str, Any] = self.build_dags()
  File "/home/airflow/.local/lib/python3.8/site-packages/dagfactory/dagfactory.py", line 117, in build_dags
    raise DagFactoryException(
dagfactory.exceptions.DagFactoryException: Failed to generate dag example_dag1. verify config is correct
[2024-03-29T17:38:49.476+0000] {processor.py:842} WARNING - No viable dags retrieved from /opt/airflow/dags/emr_add_step_dag.py
[2024-03-29T17:38:49.495+0000] {processor.py:183} INFO - Processing /opt/airflow/dags/emr_add_step_dag.py took 0.275 seconds
[2024-03-29T17:39:19.598+0000] {processor.py:161} INFO - Started process (PID=104) to work on /opt/airflow/dags/emr_add_step_dag.py
[2024-03-29T17:39:19.598+0000] {processor.py:830} INFO - Processing file /opt/airflow/dags/emr_add_step_dag.py for tasks to queue
[2024-03-29T17:39:19.600+0000] {logging_mixin.py:188} INFO - [2024-03-29T17:39:19.600+0000] {dagbag.py:540} INFO - Filling up the DagBag from /opt/airflow/dags/emr_add_step_dag.py
[2024-03-29T17:39:19.841+0000] {logging_mixin.py:188} WARNING - /home/airflow/.local/lib/python3.8/site-packages/airflow/models/baseoperator.py:437 RemovedInAirflow3Warning: provide_context is deprecated as of 2.0 and is no longer required
[2024-03-29T17:39:19.845+0000] {logging_mixin.py:188} INFO - [2024-03-29T17:39:19.842+0000] {dagbag.py:350} ERROR - Failed to import: /opt/airflow/dags/emr_add_step_dag.py
Traceback (most recent call last):
  File "/home/airflow/.local/lib/python3.8/site-packages/dagfactory/dagfactory.py", line 114, in build_dags
    dag: Dict[str, Union[str, DAG]] = dag_builder.build()
  File "/home/airflow/.local/lib/python3.8/site-packages/dagfactory/dagbuilder.py", line 856, in build
    operator: str = task_conf["operator"]
KeyError: 'operator'

The above exception was the direct cause of the following exception:

Traceback (most recent call last):
  File "/home/airflow/.local/lib/python3.8/site-packages/airflow/models/dagbag.py", line 346, in parse
    loader.exec_module(new_module)
  File "<frozen importlib._bootstrap_external>", line 843, in exec_module
  File "<frozen importlib._bootstrap>", line 219, in _call_with_frames_removed
  File "/opt/airflow/dags/emr_add_step_dag.py", line 27, in <module>
    dag_factory.clean_dags(globals())
  File "/home/airflow/.local/lib/python3.8/site-packages/dagfactory/dagfactory.py", line 152, in clean_dags
    dags: Dict[str, Any] = self.build_dags()
  File "/home/airflow/.local/lib/python3.8/site-packages/dagfactory/dagfactory.py", line 117, in build_dags
    raise DagFactoryException(
dagfactory.exceptions.DagFactoryException: Failed to generate dag example_dag1. verify config is correct
[2024-03-29T17:39:19.845+0000] {processor.py:842} WARNING - No viable dags retrieved from /opt/airflow/dags/emr_add_step_dag.py
[2024-03-29T17:39:19.870+0000] {processor.py:183} INFO - Processing /opt/airflow/dags/emr_add_step_dag.py took 0.275 seconds
[2024-03-29T17:39:49.912+0000] {processor.py:161} INFO - Started process (PID=112) to work on /opt/airflow/dags/emr_add_step_dag.py
[2024-03-29T17:39:49.913+0000] {processor.py:830} INFO - Processing file /opt/airflow/dags/emr_add_step_dag.py for tasks to queue
[2024-03-29T17:39:49.915+0000] {logging_mixin.py:188} INFO - [2024-03-29T17:39:49.914+0000] {dagbag.py:540} INFO - Filling up the DagBag from /opt/airflow/dags/emr_add_step_dag.py
[2024-03-29T17:39:50.167+0000] {logging_mixin.py:188} WARNING - /home/airflow/.local/lib/python3.8/site-packages/airflow/models/baseoperator.py:437 RemovedInAirflow3Warning: provide_context is deprecated as of 2.0 and is no longer required
[2024-03-29T17:39:50.170+0000] {logging_mixin.py:188} INFO - [2024-03-29T17:39:50.168+0000] {dagbag.py:350} ERROR - Failed to import: /opt/airflow/dags/emr_add_step_dag.py
Traceback (most recent call last):
  File "/home/airflow/.local/lib/python3.8/site-packages/dagfactory/dagfactory.py", line 114, in build_dags
    dag: Dict[str, Union[str, DAG]] = dag_builder.build()
  File "/home/airflow/.local/lib/python3.8/site-packages/dagfactory/dagbuilder.py", line 856, in build
    operator: str = task_conf["operator"]
KeyError: 'operator'

The above exception was the direct cause of the following exception:

Traceback (most recent call last):
  File "/home/airflow/.local/lib/python3.8/site-packages/airflow/models/dagbag.py", line 346, in parse
    loader.exec_module(new_module)
  File "<frozen importlib._bootstrap_external>", line 843, in exec_module
  File "<frozen importlib._bootstrap>", line 219, in _call_with_frames_removed
  File "/opt/airflow/dags/emr_add_step_dag.py", line 27, in <module>
    dag_factory.clean_dags(globals())
  File "/home/airflow/.local/lib/python3.8/site-packages/dagfactory/dagfactory.py", line 152, in clean_dags
    dags: Dict[str, Any] = self.build_dags()
  File "/home/airflow/.local/lib/python3.8/site-packages/dagfactory/dagfactory.py", line 117, in build_dags
    raise DagFactoryException(
dagfactory.exceptions.DagFactoryException: Failed to generate dag example_dag1. verify config is correct
[2024-03-29T17:39:50.171+0000] {processor.py:842} WARNING - No viable dags retrieved from /opt/airflow/dags/emr_add_step_dag.py
[2024-03-29T17:39:50.194+0000] {processor.py:183} INFO - Processing /opt/airflow/dags/emr_add_step_dag.py took 0.285 seconds
[2024-03-29T17:40:20.227+0000] {processor.py:161} INFO - Started process (PID=120) to work on /opt/airflow/dags/emr_add_step_dag.py
[2024-03-29T17:40:20.228+0000] {processor.py:830} INFO - Processing file /opt/airflow/dags/emr_add_step_dag.py for tasks to queue
[2024-03-29T17:40:20.229+0000] {logging_mixin.py:188} INFO - [2024-03-29T17:40:20.229+0000] {dagbag.py:540} INFO - Filling up the DagBag from /opt/airflow/dags/emr_add_step_dag.py
[2024-03-29T17:40:20.532+0000] {logging_mixin.py:188} WARNING - /home/airflow/.local/lib/python3.8/site-packages/airflow/models/baseoperator.py:437 RemovedInAirflow3Warning: provide_context is deprecated as of 2.0 and is no longer required
[2024-03-29T17:40:20.535+0000] {logging_mixin.py:188} INFO - [2024-03-29T17:40:20.533+0000] {dagbag.py:350} ERROR - Failed to import: /opt/airflow/dags/emr_add_step_dag.py
Traceback (most recent call last):
  File "/home/airflow/.local/lib/python3.8/site-packages/dagfactory/dagfactory.py", line 114, in build_dags
    dag: Dict[str, Union[str, DAG]] = dag_builder.build()
  File "/home/airflow/.local/lib/python3.8/site-packages/dagfactory/dagbuilder.py", line 856, in build
    operator: str = task_conf["operator"]
KeyError: 'operator'

The above exception was the direct cause of the following exception:

Traceback (most recent call last):
  File "/home/airflow/.local/lib/python3.8/site-packages/airflow/models/dagbag.py", line 346, in parse
    loader.exec_module(new_module)
  File "<frozen importlib._bootstrap_external>", line 843, in exec_module
  File "<frozen importlib._bootstrap>", line 219, in _call_with_frames_removed
  File "/opt/airflow/dags/emr_add_step_dag.py", line 27, in <module>
    dag_factory.clean_dags(globals())
  File "/home/airflow/.local/lib/python3.8/site-packages/dagfactory/dagfactory.py", line 152, in clean_dags
    dags: Dict[str, Any] = self.build_dags()
  File "/home/airflow/.local/lib/python3.8/site-packages/dagfactory/dagfactory.py", line 117, in build_dags
    raise DagFactoryException(
dagfactory.exceptions.DagFactoryException: Failed to generate dag example_dag1. verify config is correct
[2024-03-29T17:40:20.536+0000] {processor.py:842} WARNING - No viable dags retrieved from /opt/airflow/dags/emr_add_step_dag.py
[2024-03-29T17:40:20.552+0000] {processor.py:183} INFO - Processing /opt/airflow/dags/emr_add_step_dag.py took 0.329 seconds
[2024-03-29T17:40:51.449+0000] {processor.py:161} INFO - Started process (PID=128) to work on /opt/airflow/dags/emr_add_step_dag.py
[2024-03-29T17:40:51.450+0000] {processor.py:830} INFO - Processing file /opt/airflow/dags/emr_add_step_dag.py for tasks to queue
[2024-03-29T17:40:51.452+0000] {logging_mixin.py:188} INFO - [2024-03-29T17:40:51.452+0000] {dagbag.py:540} INFO - Filling up the DagBag from /opt/airflow/dags/emr_add_step_dag.py
[2024-03-29T17:40:51.743+0000] {logging_mixin.py:188} WARNING - /home/airflow/.local/lib/python3.8/site-packages/airflow/models/baseoperator.py:437 RemovedInAirflow3Warning: provide_context is deprecated as of 2.0 and is no longer required
[2024-03-29T17:40:51.745+0000] {logging_mixin.py:188} INFO - [2024-03-29T17:40:51.744+0000] {dagbag.py:350} ERROR - Failed to import: /opt/airflow/dags/emr_add_step_dag.py
Traceback (most recent call last):
  File "/home/airflow/.local/lib/python3.8/site-packages/dagfactory/dagfactory.py", line 114, in build_dags
    dag: Dict[str, Union[str, DAG]] = dag_builder.build()
  File "/home/airflow/.local/lib/python3.8/site-packages/dagfactory/dagbuilder.py", line 856, in build
    operator: str = task_conf["operator"]
KeyError: 'operator'

The above exception was the direct cause of the following exception:

Traceback (most recent call last):
  File "/home/airflow/.local/lib/python3.8/site-packages/airflow/models/dagbag.py", line 346, in parse
    loader.exec_module(new_module)
  File "<frozen importlib._bootstrap_external>", line 843, in exec_module
  File "<frozen importlib._bootstrap>", line 219, in _call_with_frames_removed
  File "/opt/airflow/dags/emr_add_step_dag.py", line 27, in <module>
    dag_factory.clean_dags(globals())
  File "/home/airflow/.local/lib/python3.8/site-packages/dagfactory/dagfactory.py", line 152, in clean_dags
    dags: Dict[str, Any] = self.build_dags()
  File "/home/airflow/.local/lib/python3.8/site-packages/dagfactory/dagfactory.py", line 117, in build_dags
    raise DagFactoryException(
dagfactory.exceptions.DagFactoryException: Failed to generate dag example_dag1. verify config is correct
[2024-03-29T17:40:51.746+0000] {processor.py:842} WARNING - No viable dags retrieved from /opt/airflow/dags/emr_add_step_dag.py
[2024-03-29T17:40:51.768+0000] {processor.py:183} INFO - Processing /opt/airflow/dags/emr_add_step_dag.py took 0.322 seconds
